Workbook

Sheet Progress
B3: Outreach Progress
C4: Total | D4: Percent | E4: Calls Per
B5: Total Prospects Called | C5: =COUNTA(Nonprofits!C:C) -> 79 | D5: =C5/300 -> 0.26333333 | E5: 1
B6: VM's | C6: =SUM(Nonprofits!AB:AB) -> 60 | D6: =C6/C5 -> 0.75949367 | E6: =$C$5/C6 -> 1.3166667
B7: Talked to Someone | C7: =SUM(Nonprofits!AC:AC) -> 20 | D7: =C7/$C$5 -> 0.25316456 | E7: =$C$5/C7 -> 3.95
B8: Sent Info Email | C8: =SUM(Nonprofits!AD:AD) -> 11 | D8: =C8/$C$5 -> 0.13924051 | E8: =$C$5/C8 -> 7.1818182
B9: Talked to Decision Maker | C9: =SUM(Nonprofits!AE:AE) -> 8 | D9: =C9/$C$5 -> 0.10126582 | E9: =$C$5/C9 -> 9.875
B10: Verbal Yes | C10: =COUNTIF('Beta Group'!B:L,"2. Yes") -> 0 | D10: =C10/$C$5 -> 0 | E10: =$C$5/C10 -> #DIV/0!
B11: Forms Filled Out | C11: =COUNTIF('Beta Group'!B:L,"3. Filled out questionnaire ") -> 3 | D11: =C11/$C$5 -> 0.037974684 | E11: =$C$5/C11 -> 26.333333

Sheet Beta Group
B2: Beta Group | N2: Outreach Progress
B3: Status | C3: Company | D3: Contact Name | E3: State | F3: Contact Date | G3: Phone Number | H3: Email | I3: Website | J3: Contact Method | K3: Notes | L3: Follow Up Date | O3: Nonprofits | Q3: Restaurants | S3: Gov Contractors | U3: Total
B4: 1. Gave feedback | C4: Senior Network Services | D4: Mariam | E4: CA | F4: 45610 | G4: 831-216-6132 | H4: mariama@seniornetworkservices.org | I4: https://seniornetworkservices.org/ | J4: Cold Call | K4: 11-14-2025 - Called, left VM. She called back and said she consults other nonprofits on doing this, asked how we're different than grant watch, and said she wants to be able to opt out in case she gets too many emails(concerned about getting too many emails) | N4: Total Called | O4: =Progress!C5 -> 79 | P4: =Progress!D5 -> 0.26333333 | Q4: =Restaurants!J3 -> 6 | R4: =Restaurants!K3 -> 0.02 | S4: ='Gov Contractors'!D3 -> 5 | T4: ='Gov Contractors'!E3 -> 0.016666667 | U4: =SUM(S4,Q4,O4) -> 90 | V4: =U4/900 -> 0.1
B5: 1. Gave feedback | C5: Anaheim Memorial Manor Inc | D5: Andy | E5: CA | F5: 45975 | G5: 5622575100 | H5: andy.do@rhf.org | J5: Cold Call | K5: 11/14/2025 - Asked to talk to the person that does grant acquisition. Got transferred to Andy. He said sure might as well. Sent him the email with the survey while on the call. He said he'd fill it out after passing it through IT to make sure the link is safe. | N5: VM's | O5: =Progress!C6 -> 60 | P5: =Progress!D6 -> 0.75949367 | Q5: =Restaurants!J4 -> 3 | R5: =Restaurants!K4 -> 0.5 | S5: ='Gov Contractors'!D4 -> 5 | T5: ='Gov Contractors'!E4 -> 1 | U5: =SUM(S5,Q5,O5) -> 68 | V5: =U5/U4 -> 0.75555556
B6: 1. Gave feedback | C6: Patient Safety Movement Foundation | D6: Consuelo | E6: CA | F6: 45966 | G6: 9492307588 | H6: info@psmf.org | I6: https://PSMF.ORG | J6: Cold Call | K6: 11/5/2025 - info@psmf.org - consuelo answered and said that michael wasn't available but that it sound interesting. 11/12/2025 - my email was flagged as spam so she didn't see it. She see's it now and is going to talk to her manager Michael tomorrow during their meeting. She's hoping I can send more info to help me seem like a legitimate thing (website? linkedin? CV?). Also said this sounds interesting because they have such a broad focus that it takes a lot to parse through all the potential grants and find one that's a good match. She also mentioned that they don't have a grant manager and that it would be helpful to mark in the questionnair what kind of time frame of grants they're looking for. | N6: Talked to Someone | O6: =Progress!C7 -> 20 | P6: =Progress!D7 -> 0.25316456 | Q6: =Restaurants!J5 -> 3 | R6: =Restaurants!K5 -> 0.5 | S6: ='Gov Contractors'!D5 -> 1 | T6: ='Gov Contractors'!E5 -> 0.2 | U6: =SUM(S6,Q6,O6) -> 24 | V6: =U6/U4 -> 0.26666667
B7: 2. Recieved Report | C7: Ka Ulukoa | D7: Lee Lamb | E7: HI | F7: 45973 | G7: (808) 741-1276 | H7: lamb@kaulukoa.org | I7: https://www.kaulukoa.org/ | J7: Cold Email | K7: 11/12/2025 - He responded: "This email address is fine, admin@kaulukoa.org. Thanks." | N7: Sent Info Email | O7: =Progress!C11 -> 3 | P7: =Progress!D11 -> 0.037974684 | Q7: =Restaurants!J6 -> 1 | R7: =Restaurants!K6 -> 0.16666667 | S7: ='Gov Contractors'!D6 -> 0 | T7: ='Gov Contractors'!E6 -> 0 | U7: =SUM(S7,Q7,O7) -> 4 | V7: =U7/U4 -> 0.044444444
B8: 2. Recieved Report | C8: Arborbrook Christian Academy | D8: Derek Durst | E8: NC | F8: 45973 | G8: (704) 821-9952 | H8: derek.durst@arborbrook.org | I8: https://www.arborbrook.org/ | J8: Cold Email | K8: 11/12/2025 - "Yes, I would be interested. This is the best email ". As in use this email to send the alerts | N8: Talked to Decision Maker | O8: =Progress!#REF! -> #REF! | P8: =Progress!#REF! -> #REF! | Q8: =Restaurants!J7 -> 4 | R8: =Restaurants!K7 -> 0.66666667 | S8: ='Gov Contractors'!D7 -> 0 | T8: ='Gov Contractors'!E7 -> 0 | U8: =SUM(S8,Q8,O8) -> #REF! | V8: =U8/U4 -> #REF!
B9: 3. Filled out questionnaire | C9: Horizons National Student Enrichment Program Inc. | D9: Alex Hoffmaster | E9: MA | H9: ahoffmaster@horizonsnational.org
B10: 3. Filled out questionnaire | C10: Highland Lakes Family Crisis Center | D10: Hardaway | E10: TX | F10: 46006 | H10: jhardaway@gmail.com
B11: 3. Filled out questionnaire | C11: Friendship Circle SD INC. | D11: Yossi Rodal | E11: CA | H11: rabbiyossi@friendshipsd.org
B13: 4. Interested | C13: Catalina Island Conservancy | D13: Kristine Partridge | E13: CA | F13: 45968 | G13: 562-437-8555 | H13: kristinepartridge@me.com | I13: https://catalinaconservancy.org/ | J13: Linkedin | K13: 11/10/2025 - Said she wouldn't mind getting the emails.
B14: 4. Interested | C14: Sonoma County Farm Bureau | D14: Brooke | E14: CA | F14: 45967 | G14: 7075445575 | H14: Brooke@sonomafb.org | I14: https://WWW.SONOMAFB.ORG | J14: Cold Call | K14: 11/6/2025 - Talked to Brooke, she gave me her email and said to send an email to her and then she'll forward it to Dayna who'll be the one that decides. Brooke@sonomafb.org 11/12/2025 - Also got put in spam - she said to send over my linkedin and she'd forward all three emails/info for Dayna to look at and decide if they want to join. She asked if I was with a company and I explained a bit about my background and how I'm testing out something I've built on the side.
B15: 4. Interested | C15: Children Today Inc | D15: Fernanda | E15: CA | F15: 45967 | G15: 5629978800 | H15: Alexis@childrentoday.org | I15: https://WWW.CHILDRENTODAY.ORG | J15: Cold Call | K15: 11/6/2025 - Fernanda said she'd let Alexis know I called. Alexis@childrentoday.org. 11/12/2025 - Alexis answered and said that Elia is the right person to talk to and gave me her email: elia@childrentoday.org.
B16: 5. Check Back Later | C16: Bikur Cholim | D16: Lucky | E16: CA | F16: 45966 | G16: 3238521900 | H16: info@bikurcholim.net | I16: https://WWW.BIKURCHOLIM.NET | J16: Cold Call | K16: 11/5/2025 - Lucky - Director. Needs Review, how do they connect to it etc(said make the email as detailed as possible so they can look into it. - info@bikurcholim.net. 11/12/2025 - Working through a lot right now (technical challenges etc with other things(I guess they just migrated all of their systems to mac book) - Let them know when we launch, and then reach out again in six months when they're probably more settled and they'll be able to focus on it. REACH OUT WHEN LAUNCHING AND IN SIX MONTHS(5/12/2025) | L16: 45789
B17: 5. Send info | C17: AFRICAN AMERICAN CULTURAL CENTER | D17: JOANNA FARRIS | E17: CA | F17: 46003 | G17: 4089106958 | H17: Jmfarris@netzero.net | J17: Cold Call | K17: 12/12 - Send email with info and she’ll take it to the business development (sales & marketing?) Meeting next week. “Probably nothing will happen until next year”

Sheet Summary
B2: Outreach Progress
C3: Nonprofits | E3: Restaurants | G3: Gov Contractors | I3: Total
B4: Total Called | C4: =Nonprofits!#REF! -> #REF! | D4: =Nonprofits!#REF! -> #REF! | E4: =Restaurants!#REF! -> #REF! | F4: =Restaurants!#REF! -> #REF! | G4: ='Gov Contractors'!#REF! -> #REF! | H4: ='Gov Contractors'!#REF! -> #REF! | I4: =SUM(G4,E4,C4) -> #REF! | J4: =I4/900 -> #REF!
B5: VM's | C5: =Nonprofits!#REF! -> #REF! | D5: =Nonprofits!#REF! -> #REF! | E5: =Restaurants!#REF! -> #REF! | F5: =Restaurants!#REF! -> #REF! | G5: ='Gov Contractors'!#REF! -> #REF! | H5: ='Gov Contractors'!#REF! -> #REF! | I5: =SUM(G5,E5,C5) -> #REF! | J5: =I5/I4 -> #REF!
B6: Talked to Someone | C6: =Nonprofits!#REF! -> #REF! | D6: =Nonprofits!#REF! -> #REF! | E6: =Restaurants!#REF! -> #REF! | F6: =Restaurants!#REF! -> #REF! | G6: ='Gov Contractors'!#REF! -> #REF! | H6: ='Gov Contractors'!#REF! -> #REF! | I6: =SUM(G6,E6,C6) -> #REF! | J6: =I6/I4 -> #REF!
B7: Sent Info Email | C7: =Nonprofits!#REF! -> #REF! | D7: =Nonprofits!#REF! -> #REF! | E7: =Restaurants!#REF! -> #REF! | F7: =Restaurants!#REF! -> #REF! | G7: ='Gov Contractors'!#REF! -> #REF! | H7: ='Gov Contractors'!#REF! -> #REF! | I7: =SUM(G7,E7,C7) -> #REF! | J7: =I7/I4 -> #REF!
B8: Talked to Decision Maker | C8: =Nonprofits!#REF! -> #REF! | D8: =Nonprofits!#REF! -> #REF! | E8: =Restaurants!#REF! -> #REF! | F8: =Restaurants!#REF! -> #REF! | G8: ='Gov Contractors'!#REF! -> #REF! | H8: ='Gov Contractors'!#REF! -> #REF! | I8: =SUM(G8,E8,C8) -> #REF! | J8: =I8/I4 -> #REF!

Sheet Sheet3
B2: Status
B3: 1. Gave feedback | C3: 1 | D3: Yes
B4: 2. Recieved Report | C4: 0 | D4: No
B5: 3. Filled out questionnaire | D5: Maybe
B6: 4. Interested | D6: No Answer Try Again
B7: 5. Send info | D7: Gatekeeper Will Give Message
B8: 6. Check Back Later
B9: 7. Not Interested

Sheet Pipeline Lists
B2: Verticals | C2: Yes/No/Maybe
B3: Nonprofits | C3: Yes | D3: 1
B4: Restaurants | C4: No | D4: 0
B5: Gov. Contractors | C5: Maybe
C6: Uncertain

Sheet Nonprofits
B2: Organization_Name | C2: Contact Date | D2: Phone | E2: Officer_Name | F2: Officer_Title | G2: Mission Statement | H2: Website | I2: Address | J2: City | K2: State | L2: employee_count | M2: volunteer_count | N2: ZIP | O2: Website2 | P2: Total_Revenue | Q2: Grants_Revenue | R2: Grant_Dependency_Pct | S2: Total_Expenses | T2: Mission | U2: Max Weekly Hours | V2: NTEE_Codes | W2: Tax_Year | X2: EIN | Y2: Prospect_Score | Z2: Decision Maker | AA2: Decision Maker Title | AB2: VM/Message | AC2: Talked to Someone | AD2: Send us an Email | AE2: Reached Decision Maker | AF2: Yes/No/Maybe/Uncertain | AG2: Notes
B3: COACHELLA VALLEY REPERTORY | C3: 45966 | D3: 7602962966 | E3: NICOLE TAYLOR CPA | F3: TREASURER | I3: 68510 E PALM CANYON DR | J3: CATHEDRAL CITY | K3: CA | N3: 922341300 | O3: https://CVREP.ORG | P3: 2012562 | Q3: 894440 | R3: 44.4 | S3: 2279846 | T3: COACHELLA VALLEY REPERTORY IS AN EDUCATIONAL, DRAMATIC AND MUSICAL THEATRE ORGANIZATION THAT OFFERS THOUGHT-PROVOKING, INNOVATIVE THEATER OF SUBSTANCE, AND A VOICE TO A WIDE RANGE OF ARTISTS AND VISIONS. CVREP PROVIDES PRODUCTIONS AND OUTREACH PROGRAMS THAT POSITIVELY ENRICH, ENHANCE AND IMPACT THE | U3: {=MAX(_xlfn._xlws.FILTER('Email Outreach Prospects'!F:F, 'Email Outreach Prospects'!B:B=B3))} -> 40 | V3: A, B | W3: 2023 | X3: 954304295 | Y3: 10 | Z3: Joe | AA3: CFO | AB3: 1 | AC3: 0 | AD3: 0 | AE3: 0 | AF3: Uncertain | AG3: No Answer - VM for Joe, CFO
B4: UJIMA ADULT AND FAMILY SERVICES INC | C4: 45966 | D4: 4089281700 | E4: YVONNE MAXWELL | F4: EXECUTIVE DIRECTOR | I4: 1898 THE ALAMEDA | J4: SAN JOSE | K4: CA | N4: 95126 | O4: http://www.ujimaagency.org | P4: 1860541 | Q4: 1779408 | R4: 95.6 | S4: 1697991 | T4: TO PROVIDE AFRICENTRIC MENTAL HEALTH, COUNSELING, AND SUPPORT SERVICES TO THE AFRICAN AMERICAN COMMUNITY THROUGH FOCUSING ON AFRICAN HISTORY, CULTURAL NORMS, AND VALUES | U4: {=MAX(_xlfn._xlws.FILTER('Email Outreach Prospects'!F:F, 'Email Outreach Prospects'!B:B=B4))} -> 40 | V4: A, E, P | W4: 2023 | X4: 770376995 | Y4: 10 | AB4: 1 | AC4: 1 | AD4: 0 | AE4: 0 | AF4: Uncertain | AG4: Gave Operator 12 a message
B5: BURLINGTON COMM SRVS & HOUSING DEV | C5: 45966 | D5: 2134830928 | E5: CECILIA C RAMOS | F5: ADMINISTRATOR | I5: 242 N BURLINGTON AVE | J5: LOS ANGELES | K5: CA | N5: 90026 | O5: https://X | P5: 1286407 | Q5: 1286407 | R5: 100 | S5: 1286407 | T5: TO PROVIDE DAYCARE SERVICES TO LOW AND MODERATE INCOME FAMILIES AND WELFARE RECIPIENTS. | U5: {=MAX(_xlfn._xlws.FILTER('Email Outreach Prospects'!F:F, 'Email Outreach Prospects'!B:B=B5))} -> 1 | V5: P, S | W5: 2023 | X5: 510181441 | Y5: 10 | AB5: 1 | AC5: 1 | AD5: 0 | AE5: 0 | AF5: Uncertain | AG5: burlingtonschoolinc@gmail.com, Maree -- Said to send email, kind of hard to understand with accent(and may not of understood me very well)
B6: Career Technical Education Foundation Sonoma County | C6: 45966 | D6: 7077087080 | E6: Kathy Goodacre | F6: CEO | I6: 1030 Apollo Way 200 | J6: Santa Rosa | K6: CA | N6: 95407 | O6: https://www.ctesonomacounty.org | P6: 2798209 | Q6: 2780988 | R6: 99.4 | S6: 2355047 | T6: INNOVATING THE EDUCATION-TO-CAREER EXPERIENCE TO STRENGTHEN ECONOMIC DEVELOPMENT AND STUDENT SUCCESS. | U6: {=MAX(_xlfn._xlws.FILTER('Email Outreach Prospects'!F:F, 'Email Outreach Prospects'!B:B=B6))} -> 40 | V6: B, S | W6: 2023 | X6: 465607272 | Y6: 10 | AB6: 1 | AC6: 0 | AD6: 0 | AE6: 0 | AF6: Uncertain | AG6: Left VM
B7: COUNCIL OF CHIEF LIBRARIANS | C7: 45966 | D7: 5309088810 | E7: GREGG ATKINS | F7: Director | I7: 1809 S ST STE 101-172 | J7: SACRAMENTO | K7: CA | N7: 95811 | O7: https://CCLIBRARIANS.ORG | P7: 1715620 | Q7: 1702345 | R7: 99.2 | S7: 1452686 | T7: TO REPRESENT, PROMOTE AND ADVANCE LIBRARIES IN PUBLIC CALIFORNIA COMMUNITY COLLEGE EDUCATION. TO PROVIDE A VEHICLE FOR COMMUNICATION, DISCUSSION, AND COLLABORATION AMONG CHIEF LIBRARIANS. TO PROVIDE OPPORTUNITIES FOR PROFESSIONAL DEVELOPMENT, TRAINING, AND LEADERSHIP OF CHIEF AND OTHER ACADEMIC LIBR | U7: {=MAX(_xlfn._xlws.FILTER('Email Outreach Prospects'!F:F, 'Email Outreach Prospects'!B:B=B7))} -> 5 | V7: A, B | W7: 2023 | X7: 954214083 | Y7: 10 | Z7: GREGG ATKINS | AA7: Director | AB7: 1 | AC7: 0 | AD7: 0 | AE7: 0 | AF7: Uncertain | AG7: Left VM - voiemailbox for Gregg
B8: Fair Housing Advocates of Northern California | C8: 45966 | D8: 4154575025 | E8: Caroline Peattie | F8: Executive Director | I8: 851 Irwin Street Suite 218 | J8: San Rafael | K8: CA | N8: 94901 | O8: https://www.fairhousingnorcal.org | P8: 1839889 | Q8: 1224928 | R8: 66.6 | S8: 1961348 | T8: We provide fair housing, pre-purchase, and mortgage foreclosure prevention services in Marin, Sonoma, and Solano counties, with advisory training in other counties. Our services to tenants and homeowners are available at no charge in English and Spanish. | U8: {=MAX(_xlfn._xlws.FILTER('Email Outreach Prospects'!F:F, 'Email Outreach Prospects'!B:B=B8))} -> 37.5 | V8: B, S | W8: 2023 | X8: 680087976 | Y8: 10 | AB8: 1 | AC8: 0 | AD8: 0 | AE8: 0 | AF8: Uncertain | AG8: Left VM
B9: Legal Aid Association of California | C9: 45966 | D9: 5108933000 | E9: Salena Copeland | F9: Executive Dir. | I9: 1832 Second Street Suite 105 | J9: Berkeley | K9: CA | N9: 94710 | O9: https://www.laaconline.org | P9: 1644600 | Q9: 1532722 | R9: 93.2 | S9: 1566417 | T9: The Legal Aid Association of California, the statewide membership of legal services nonprofits, serves its members through advocacy and other support in efforts to provide legal assistance to low-income Californians and ensure access to justice. | U9: {=MAX(_xlfn._xlws.FILTER('Email Outreach Prospects'!F:F, 'Email Outreach Prospects'!B:B=B9))} -> 40 | V9: B | W9: 2023 | X9: 330042690 | Y9: 10 | AB9: 1 | AC9: 0 | AD9: 0 | AE9: 0 | AF9: Uncertain | AG9: Left VM
B10: Scientific Adventures dba Scientific | C10: 45966 | D10: 4155315288 | E10: Courtenay Carr Heuer | F10: Executive Dir. | I10: PO Box 11123 | J10: Oakland | K10: CA | N10: 94611 | O10: https://www.scientificadventures.org | P10: 1142976 | Q10: 855271 | R10: 74.8 | S10: 907002 | T10: To remove systemic barriers to all girls participation in STEM starting in transitional kindergarten, engage them through hands-on learning, increase their positive attitudes toward STEM, and equip them with 21st century skills. | U10: {=MAX(_xlfn._xlws.FILTER('Email Outreach Prospects'!F:F, 'Email Outreach Prospects'!B:B=B10))} -> 40 | V10: A, B | W10: 2023 | X10: 472414936 | Y10: 10 | Z10: Courtenay Carr Heuer | AA10: Executive Dir. | AB10: 1 | AC10: 0 | AD10: 0 | AE10: 0 | AF10: Uncertain | AG10: Left VM - voiemailbox for courtenay
B11: Santa Ynez Valley Charter School Inc | C11: 45966 | D11: 8056867363 | E11: Matt Stockton | F11: Board President | I11: 1224 Tyndall Street | J11: Santa Ynez | K11: CA | N11: 93460 | O11: https://www.syvcs.org | P11: 2102762 | Q11: 1939880 | R11: 92.3 | S11: 2102803 | T11: To work collaboratively to create a supportive innovative and academically challenging educational environment that nurtures its students and prepares them for high school and beyond through close curricular articulation. | U11: {=MAX(_xlfn._xlws.FILTER('Email Outreach Prospects'!F:F, 'Email Outreach Prospects'!B:B=B11))} -> 40 | V11: B, C | W11: 2022 | X11: 770552159 | Y11: 10 | AB11: 1 | AC11: 0 | AD11: 0 | AE11: 0 | AF11: Uncertain | AG11: Left VM
B12: Project Hope Alliance | C12: 45966 | D12: 9497227824 | E12: JENNIFER FRIEND | F12: CEO | I12: 1954 Placentia Avenue Suite 202 | J12: Costa Mesa | K12: CA | N12: 92627 | O12: https://www.projecthopealliance.org | P12: 3045129 | Q12: 2387123 | R12: 78.4 | S12: 2991624 | T12: THE MISSION OF PROJECT HOPE ALLIANCE IS TO END THE CYCLE OF HOMELESSNESS, ONE CHILD AT A TIME. OUR VISION IS EQUIPPING HOMELESS CHILDREN WITH THE TOOLS AND OPPORTUNITIES TO LEARN THEIR WAY TO A BETTER TOMORROW. | U12: {=MAX(_xlfn._xlws.FILTER('Email Outreach Prospects'!F:F, 'Email Outreach Prospects'!B:B=B12))} -> 40 | V12: P | W12: 2023 | X12: 753099628 | Y12: 10 | Z12: JENNIFER FRIEND | AA12: CEO | AB12: 1 | AC12: 0 | AD12: 0 | AE12: 0 | AF12: Uncertain | AG12: Left VM - voiemailbox for Jennifer
B13: STARTX | C13: 45966 | D13: 6502839206 | E13: SHANNON MCCLENAGHAN | F13: DIRECTOR | I13: 2627 HANOVER ST | J13: PALO ALTO | K13: CA | N13: 94304 | O13: https://STARTX.COM | P13: 1809968 | Q13: 1534495 | R13: 84.8 | S13: 2321609 | T13: STARTX IS A NONPROFIT EDUCATIONAL PROGRAM RUN PRIMARILY BY ALUMNI AND STUDENTS OF STANFORD UNIVERSITY. THE MISSION OF STARTX IS TO ACCELERATE THE DEVELOPMENT OF HIGH-POTENTIAL, STANFORD ENTREPRENEURS THROUGH EXPERIENTIAL EDUCATION. | U13: {=MAX(_xlfn._xlws.FILTER('Email Outreach Prospects'!F:F, 'Email Outreach Prospects'!B:B=B13))} -> 60 | V13: B | W13: 2023 | X13: 454308444 | Y13: 10 | AB13: 1 | AC13: 0 | AD13: 0 | AE13: 0
B14: PATIENT SAFETY MOVEMENT FOUNDATION | C14: 45966 | D14: 9492307588 | E14: MICHAEL AE RAMSAY | F14: MD CEO | I14: 15642 SAND CANYON AVE STE 51268 | J14: IRVINE | K14: CA | N14: 92619 | O14: https://PSMF.ORG | P14: 2096479 | Q14: 2063971 | R14: 98.4 | S14: 2189165 | T14: OUR MISSION IS TO DISSEMINATE ACTIONABLE EVIDENCE-BASED PRACTICES, ADVANCE THEIR INTEGRATION BY HEALTHCARE ORGANIZATIONS, AND CULTIVATE DATA TRANSPARENCY BY 2030. | U14: {=MAX(_xlfn._xlws.FILTER('Email Outreach Prospects'!F:F, 'Email Outreach Prospects'!B:B=B14))} -> 0 | V14: E | W14: 2023 | X14: 462730379 | Y14: 10 | Z14: Consuelo | AB14: 1 | AC14: 1 | AD14: 1 | AE14: 1 | AF14: Maybe | AG14: info@psmf.org - consuelo answered and said that michael wasn't available but that it sound interesting.
B15: NEXT DOOR SOLUTIONS TO DOMESTIC VIOLENCE | C15: 45966 | D15: 4085017550 | E15: COLSARIA HENDERSON | F15: EXECUTIVE DIRECTOR | I15: 234 EAST GISH ROAD SUITE 200 | J15: SAN JOSE | K15: CA | N15: 95112 | O15: https://WWW.NEXTDOORSOLUTIONS.ORG | P15: 4451135 | Q15: 4467191 | R15: 100.4 | S15: 4809493 | T15: TO END DOMESTIC VIOLENCE IN THE MOMENT AND FOR ALL TIME. | U15: {=MAX(_xlfn._xlws.FILTER('Email Outreach Prospects'!F:F, 'Email Outreach Prospects'!B:B=B15))} -> 40 | V15: B, P | W15: 2023 | X15: 942420708 | Y15: 10 | AB15: 1 | AC15: 0 | AD15: 0 | AE15: 0
B16: Catholic Charities of Yolo-Solano | C16: 45966 | D16: 7076448909 | E16: John Watkins | F16: Executive Director | I16: 125 Corporate Place | J16: Vallejo | K16: CA | N16: 94590 | O16: https://www.csssolano.org | P16: 1512402 | Q16: 1047412 | R16: 69.3 | S16: 1635446 | T16: OUR MISSION IS TO REACH OUT AND PROVIDE ASSISTANCE TO ANYONE IN NEED IN OUR COMMUNITY, ESPECIALLY THE POOR AND DISADVANTAGED. WE OFFER HEALTH AND SOCIAL SERVICE PROGRAMS THAT CONTRIBUTE TO THE INDIVIDUAL'S FREEDOM AND INDEPENDENCE, WHILE ALWAYS VALUING THE DIGNITY OF HUMAN LIFE AND IMPORTANCE OF FAM | U16: {=MAX(_xlfn._xlws.FILTER('Email Outreach Prospects'!F:F, 'Email Outreach Prospects'!B:B=B16))} -> 40 | V16: E, P | W16: 2022 | X16: 465010936 | Y16: 10 | AB16: 1 | AC16: 0 | AD16: 0 | AE16: 0
B17: HUNGER AT HOME | C17: 45966 | D17: 4083180038 | E17: WILLIAM STERNER | F17: PRESIDENT | I17: 1560 BERGER DRIVE | J17: SAN JOSE | K17: CA | N17: 95112 | O17: https://HUNGERATHOME.ORG | P17: 4769513 | Q17: 4767688 | R17: 100 | S17: 4888587 | T17: HUNGER AT HOME SERVES AS A CONDUIT BETWEEN THE BUSINESS COMMUNITY AND NONPROFIT PARTNERS BY WHICH EXCESS FOOD AND OTHER SURPLUS IS CHANNELED TO THE HOMELESS AND THE HUNGRY. | U17: {=MAX(_xlfn._xlws.FILTER('Email Outreach Prospects'!F:F, 'Email Outreach Prospects'!B:B=B17))} -> 40 | V17: P | W17: 2022 | X17: 475462753 | Y17: 10 | AB17: 1 | AC17: 0 | AD17: 0 | AE17: 0
B18: BIKUR CHOLIM | C18: 45966 | D18: 3238521900 | E18: HAROLD TEN | F18: PRESIDENT/CEO (Rabi Ten) | I18: 8489 WEST THIRD STREET | J18: LOS ANGELES | K18: CA | N18: 90048 | O18: https://WWW.BIKURCHOLIM.NET | P18: 1458541 | Q18: 1421416 | R18: 97.5 | S18: 874068 | T18: BIKUR CHOLIM ORGANIZES AND SUBSIDIZES MEDICAL TREATMENT, SPEECH AND PHYSICAL THERAPY, MEDICATION, DURABLE MEDICAL EQUIPMENT, BLOOD PRODUCTS, HOMECARE, TRANSPORTATION, HOUSING FOR PATIENTS AND FAMILY-MEMBERS, MEALS, AND DIAGNOSTICS WHILE PROVIDING SOCIAL SUPPORT AND ADVOCACY. | U18: {=MAX(_xlfn._xlws.FILTER('Email Outreach Prospects'!F:F, 'Email Outreach Prospects'!B:B=B18))} -> 90 | V18: E, S | W18: 2022 | X18: 954521980 | Y18: 10 | Z18: Lucky | AA18: Director | AB18: 1 | AC18: 1 | AD18: 1 | AE18: 1 | AF18: Maybe | AG18: Lucky - Director. Needs Review, how do they connect to it etc(said make the email as detailed as possible so they can look into it. - info@bikurcholim.net
B19: BUDDHIST GLOBAL RELIEF | C19: 45966 | D19: 6098644054 | E19: HILLARY CHEN | F19: Treasurer | I19: 506 BROUGHTON LANE | J19: FOSTER CITY | K19: CA | N19: 94404 | O19: https://WWW.BUDDHISTGLOBALRELIEF.ORG | P19: 1806042 | Q19: 1654299 | R19: 91.6 | S19: 1927648 | T19: TO ALLEVIATE SUFFERING, POVERTY AND OPPRESSION THROUGH DIRECT AID, ECONOMIC AND TECHINICAL ASSISTANCE, EDUCATION AND OTHER FORMS OF CHARITABLE ASSISTANCE TO PEOPLE IN NEED THROUGHTOUT THE WORLD | U19: {=MAX(_xlfn._xlws.FILTER('Email Outreach Prospects'!F:F, 'Email Outreach Prospects'!B:B=B19))} -> 30 | V19: B | W19: 2023 | X19: 262852923 | Y19: 10 | AB19: 1 | AC19: 0 | AD19: 0 | AE19: 0 | AG19: Hillary Chen's Email
B20: VILLA GREENTREE INC | C20: 45967 | D20: 5622575100 | E20: FRANK ROSSELLO | F20: CFO/V.P., FINANCE | I20: 911 NORTH STUDEBAKER ROAD | J20: LONG BEACH | K20: CA | N20: 90815 | O20: https://WWW.RHF.ORG | P20: 2347222 | Q20: 1306342 | R20: 55.7 | S20: 1950843 | T20: VILLA GREENTREE, INC. IS A NOT-FOR-PROFIT CORPORATION FORMED IN ACCORDANCE WITH THE NOT-FOR-PROFIT STATUTES OF THE STATE OF INDIANA. THE CORPORATION WAS FORMED FOR THE PURPOSE OF OPERATING A 202 UNIT COMMUNITY KNOWN AS YELLOWWOOD TERRACE LOCATED IN CLARKSVILLE, INDIANA, WHICH PROVIDES HOUSING FOR LO | U20: {=MAX(_xlfn._xlws.FILTER('Email Outreach Prospects'!F:F, 'Email Outreach Prospects'!B:B=B20))} -> 0.2 | V20: P, S | W20: 2023 | X20: 311042917 | Y20: 10 | AB20: 1 | AC20: 0 | AD20: 0 | AE20: 0 | AF20: Uncertain | AG20: Operator connected me to Frank
B21: The Clearity Foundation | C21: 45967 | D21: 8586570282 | E21: Hillary C Theakston | F21: Executive Director | I21: 8880 Rio San Diego Drive STE 800 | J21: San Diego | K21: CA | N21: 92108 | O21: https://www.clearityfoundation.org | P21: 1787046 | Q21: 1852123 | R21: 103.6 | S21: 1932061 | T21: The mission is to seek better treatment options for women with ovarian cancer by providing diagnostic services that determine the molecular profile of the individual patient and providing doctors access to molecular profiling for their ovarian cancer patients. | U21: {=MAX(_xlfn._xlws.FILTER('Email Outreach Prospects'!F:F, 'Email Outreach Prospects'!B:B=B21))} -> 0 | V21: E | W21: 2023 | X21: 261095856 | Y21: 10 | AB21: 1 | AC21: 0 | AD21: 0 | AE21: 0 | AF21: Uncertain
B22: CALIFORNIA SCHOOL BOARDS FOUNDATION | C22: 45967 | D22: 9163714691 | E22: LARE BLOODWORTH | F22: CHIEF FINANCIAL OFFICER | I22: 3251 BEACON BOULEVARD | J22: WEST SACRAMENTO | K22: CA | N22: 956913531 | O22: https://WWW.CSBA.ORG | P22: 2152782 | Q22: 2098228 | R22: 97.5 | S22: 1025597 | T22: THE MISSION OF THE CALIFORNIA SCHOOL BOARDS FOUNDATION IS TO PROVIDE EDUCATION, SUPPORT, AND TRAINING TO SCHOOL BOARD MEMBERS, CONDUCT POLICY RESEARCH AND ANALYSIS ON EDUCATION-RELATED ISSUES, TO RECOGNIZE EDUCATIONAL LEADERSHIP AND ACHIEVEMENTS IN CALIFORNIA, TO ENCOURAGE AND FACILITATE THE PROCESS | U22: {=MAX(_xlfn._xlws.FILTER('Email Outreach Prospects'!F:F, 'Email Outreach Prospects'!B:B=B22))} -> 8 | V22: B | W22: 2023 | X22: 941623582 | Y22: 10 | AB22: 1 | AC22: 0 | AD22: 0 | AE22: 0 | AF22: Uncertain
B23: SONOMA COUNTY FARM BUREAU | C23: 45967 | D23: 7075445575 | E23: JOHN BIDIA | F23: TREASURER | I23: 3589 WESTWIND BLVD | J23: SANTA ROSA | K23: CA | N23: 95403 | O23: https://WWW.SONOMAFB.ORG | P23: 1217815 | Q23: 656471 | R23: 53.9 | S23: 1098740 | T23: SEE SCHEDULE O | U23: {=MAX(_xlfn._xlws.FILTER('Email Outreach Prospects'!F:F, 'Email Outreach Prospects'!B:B=B23))} -> 0 | V23: B | W23: 2023 | X23: 941210577 | Y23: 10 | Z23: Dayna Ghirardelli | AA23: Executive Director | AB23: 1 | AC23: 1 | AD23: 1 | AE23: 0 | AF23: Uncertain | AG23: Talked to Brooke, she gave me her email and said to send an email to her and then she'll forward it to Dayna who'll be the one that decides. Brooke@sonomafb.org
B24: Satellite Senior Homes III Inc | C24: 45967 | D24: 5106470700 | E24: SUSAN FRIEDLAND | F24: CEO | I24: 1835 Alcatraz Avenue | J24: Berkeley | K24: CA | N24: 94703 | O24: https://www.sahahomes.org | P24: 2881971 | Q24: 2145260 | R24: 74.4 | S24: 2290752 | T24: TO PROVIDE LOW-INCOME ELDERLY & HANDICAPPED PERSONS WITH AFFORDABLE HOUSING FACILITIES & SERVICES SPECIALLY DESIGNED TO MEET THEIR PHYSICAL, SOCIAL & PSYCHOLOGICAL NEEDS, AND TO PROMOTE THEIR HEALTH, SECURITY, HAPPINESS & USEFULNESS IN LONGER LIVING ON A NONPROFIT BASIS. | U24: {=MAX(_xlfn._xlws.FILTER('Email Outreach Prospects'!F:F, 'Email Outreach Prospects'!B:B=B24))} -> 0.1 | V24: E, P, S | W24: 2023 | X24: 942835291 | Y24: 10 | AB24: 1 | AC24: 0 | AD24: 0 | AE24: 0 | AF24: Uncertain
B25: CHILDREN TODAY INC | C25: 45967 | D25: 5629978800 | E25: ELIA ROCHA | F25: EXECUTIVE DIRECTOR | I25: 2951 LONG BEACH BLVD | J25: LONG BEACH | K25: CA | N25: 90806 | O25: https://WWW.CHILDRENTODAY.ORG | P25: 1903027 | Q25: 1869459 | R25: 98.2 | S25: 1817646 | T25: TO PROVIDE TRAUMA-INFORMED CHILD DEVELOPMENT, PRESCHOOL, AND FAMILY SUPPORT SERVICES TO FAMILIES EXPERIENCING HOMELESSNESS, AND/OR MALTREATMENT, FOSTERING LONG-TERM STABILITY AND SUCCESS. | U25: {=MAX(_xlfn._xlws.FILTER('Email Outreach Prospects'!F:F, 'Email Outreach Prospects'!B:B=B25))} -> 40 | V25: B, P | W25: 2023 | X25: 954635295 | Y25: 10 | Z25: Alexis | AB25: 1 | AC25: 1 | AD25: 1 | AE25: 0 | AF25: Uncertain | AG25: Fernanda said she'd let Alexis know I called. Alexis@childrentoday.org
B26: Court Appointed Special Advocates | C26: 45967 | D26: 8317612956 | E26: Josue Barajas | F26: President | I26: 813 Freedom Blvd | J26: Watsonville | K26: CA | N26: 95076 | O26: https://WWW.CASAOFSANTACRUZ.ORG | P26: 1832706 | Q26: 1786616 | R26: 97.5 | S26: 2153201 | T26: CASA of Santa Cruz advocates for children and youth, providing court appointed volunteers so each child in the dependency and juvenile court system feels cared for and connected with the people, families and resources they need to heal and flourish into adulthood. | U26: {=MAX(_xlfn._xlws.FILTER('Email Outreach Prospects'!F:F, 'Email Outreach Prospects'!B:B=B26))} -> 40 | V26: P | W26: 2023 | X26: 770305354 | Y26: 10 | AB26: 1 | AC26: 0 | AD26: 0 | AE26: 0 | AF26: Uncertain
B27: FAMILY SUPPORT NETWORK | C27: 45967 | D27: 7144473301 | E27: MAURA BYRON | F27: EXECUTIVE DIRECTOR | I27: 1894 N MAIN STREET | J27: ORANGE | K27: CA | N27: 92865 | O27: https://WWW.FSN-OC.ORG | P27: 1155471 | Q27: 1143003 | R27: 98.9 | S27: 1165113 | T27: PROVIDES SERVICES OFFERING RESOURCES AND ADVOCACY FOR FAMILIES/CHILDREN WITH SOCIAL, EMOTIONAL, INTELLECTUAL AND PHYSICAL NEEDS SO THEY MAY REACH THEIR FULL POTENTIAL. | U27: {=MAX(_xlfn._xlws.FILTER('Email Outreach Prospects'!F:F, 'Email Outreach Prospects'!B:B=B27))} -> 50 | V27: P | W27: 2023 | X27: 330248195 | Y27: 10 | Z27: Moe | AA27: Byron | AB27: 1 | AC27: 1 | AD27: 0 | AE27: 0 | AF27: Uncertain | AG27: Kathia sent me to Moe's VMbox (maura byron)
B28: STUDENTS RUN AMERICA | C28: 45967 | D28: 8186543360 | E28: GABRIELA ARVIZU | F28: PRESIDENT/CEO | I28: 5252 CREBS AVENUE | J28: TARZANA | K28: CA | N28: 91356 | O28: https://WWW.SRLA.ORG | P28: 3711013 | Q28: 3515368 | R28: 94.7 | S28: 3601363 | T28: CHALLENGE UNDERSERVED SECONDARY STUDENTS TO STAY IN SCHOOL AND EXPERIENCE THE BENEFITS OF GOAL-SETTING, CHARACTER DEVELOPMENT, ADULT MENTORING AND IMPROVED HEALTH BY PROVIDING THEM WITH A LIFE-CHANGING EXPERIENCE: COMPLETING THE LA MARATHON. | U28: {=MAX(_xlfn._xlws.FILTER('Email Outreach Prospects'!F:F, 'Email Outreach Prospects'!B:B=B28))} -> 40 | V28: B, E | W28: 2023 | X28: 954430502 | Y28: 10 | AB28: 1 | AC28: 0 | AD28: 0 | AE28: 0 | AF28: Uncertain
B29: YOUNG WOMENS CHRISTIAN ASSOCIATION OF THE HARBOR AREA | C29: 45967 | D29: 3105470831 | E29: JULIE WICHMANN HUERTA | F29: PRESIDENT | I29: 437 W 9TH STREET | J29: SAN PEDRO | K29: CA | N29: 90731 | O29: https://ywcaharbor.org | P29: 1457085 | Q29: 687388 | R29: 47.2 | S29: 1356180 | T29: THE MISSION OF THE YWCA IS TO FOSTER THE ECONOMIC SELF-SUFFICIENCY, EMOTIONAL AND PHYSICAL HEALTH OF WOMEN AND GIRLS IN A WORLD OF PEACE, RACIAL JUSTICE, DIGNITY, FREEDOM AND EQUALITY FOR ALL. | U29: {=MAX(_xlfn._xlws.FILTER('Email Outreach Prospects'!F:F, 'Email Outreach Prospects'!B:B=B29))} -> 40 | V29: E | W29: 2022 | X29: 951691337 | Y29: 10 | AB29: 0 | AC29: 0 | AD29: 0 | AE29: 0 | AF29: Uncertain
B30: SENIOR NETWORK SERVICES INC | C30: 45967 | D30: 8314621433 | E30: COREY F AZEVEDO | F30: Executive Dir. | I30: 1777-A CAPITOLA ROAD | J30: SANTA CRUZ | K30: CA | N30: 95062 | O30: https://seniornetworkservices.org | P30: 1956265 | Q30: 1856854 | R30: 94.9 | S30: 2036635 | T30: Senior Network Services is a nonprofit agency providing senior citizens and persons with disabilities with information, guidance and assistance in coordinating existing resources to promote independence and the highest quality of life. | U30: {=MAX(_xlfn._xlws.FILTER('Email Outreach Prospects'!F:F, 'Email Outreach Prospects'!B:B=B30))} -> 40 | V30: P | W30: 2023 | X30: 942259716 | Y30: 10 | AB30: 1 | AC30: 0 | AD30: 0 | AE30: 0 | AF30: Uncertain | AG30: She helps people find the right fonuidatins and says it's technical. Knows the ins and outs etc. Tech for good. Social positive changes using tech. Is building an app -- targinily -signal also is anlother example of tech for good. Targinily is a tansition service for refugees- people volunteer and they translate for people around the world. Similar not translation but also tech for good.
B31: HILLSDALE HIGH SCHOOL FOUNDATION | C31: 45967 | D31: 6505582618 | E31: MARCINE JANSEN | F31: EXECUTIVE DIRECTOR | I31: 63 BOVET ROAD 218 | J31: SAN MATEO | K31: CA | N31: 94402 | O31: https://WWW.HILLSDALEHSFOUNDATION.ORG | P31: 1995846 | Q31: 1934778 | R31: 96.9 | S31: 765746 | T31: HHSF RAISES FUNDS TO SUSTAIN HILLSDALE HIGH SCHOOL'S (HHS) UNIQUE ACADEMIC ENVIRONMENT OF SMALL LEARNING COMMUNITIES (SLCS). THE SLC MODEL PROVIDES A PERSONALIZED, RIGOROUS, AND ENGAGING EDUCATION. | U31: {=MAX(_xlfn._xlws.FILTER('Email Outreach Prospects'!F:F, 'Email Outreach Prospects'!B:B=B31))} -> 25 | V31: B, C | W31: 2023 | X31: 870800728 | Y31: 10 | AB31: 1 | AC31: 0 | AD31: 0 | AE31: 0 | AF31: Uncertain
B32: SHELTER SOLANO INC | C32: 45967 | D32: 9259577595 | E32: JOHN ECKSTROM | F32: CEO | I32: PO BOX 5368 | J32: CONCORD | K32: CA | N32: 94524 | O32: https://WWW.SHELTERINC.ORG | P32: 2588611 | Q32: 2402626 | R32: 92.8 | S32: 3026486 | T32: SHELTER SOLANO IS A YEAR-ROUND EMERGENCY SHELTER LOCATED ON 3.5 ACRES IN FAIRFIELD, CA. SHELTER SOLANO CAN MEET THE EMERGENCY HOUSING NEEDS OF INDIVIDUALS AND FAMILIES WITH ACCOMMODATIONS INCLUDING DORMITORY STYLE ROOMS, FAMILY-SIZED ROOMS, AND SEPARATE APARTMENT-STYLE UNITS. THE CAMPUS IS SECURED A | U32: {=MAX(_xlfn._xlws.FILTER('Email Outreach Prospects'!F:F, 'Email Outreach Prospects'!B:B=B32))} -> 1 | V32: P, S | W32: 2023 | X32: 832704105 | Y32: 10 | AB32: 1 | AC32: 0 | AD32: 0 | AE32: 0 | AF32: Uncertain | AG32: Number goes to John's phone
B33: DIAKONIA HOUSING INC | C33: 45967 | D33: 5622575100 | E33: FRANK ROSSELLO | F33: CFO/V.P., FINANCE | I33: 911 N STUDEBAKER ROAD | J33: LONG BEACH | K33: CA | N33: 90815 | O33: https://WWW.RHF.ORG | P33: 1103085 | Q33: 655705 | R33: 59.4 | S33: 1138362 | T33: DIAKONIA HOUSING, INC. IS A NOT-FOR-PROFIT CORPORATION FORMED IN ACCORDANCE WITH THE NOT-FOR-PROFIT STATUTES OF THE STATE OF INDIANA. THE CORPORATION WAS FORMED FOR THE PURPOSE OF OPERATING A 100 UNIT COMMUNITY KNOWN AS LONGFELLOW PLAZA LOCATED IN ANDERSON, INDIANA, WHICH PROVIDES HOUSING FOR LOW IN | U33: {=MAX(_xlfn._xlws.FILTER('Email Outreach Prospects'!F:F, 'Email Outreach Prospects'!B:B=B33))} -> 0.2 | V33: P, S | W33: 2023 | X33: 953815145 | Y33: 10 | AB33: 1 | AC33: 0 | AD33: 0 | AE33: 0 | AF33: Uncertain | AG33: Operator connected me to Frank's number
B34: FRIENDSHIP HOUSE III INC | C34: 45973 | D34: 5622575100 | E34: FRANK ROSSELLO | F34: CFO/V.P., FINANCE | I34: 911 N STUDEBAKER ROAD | J34: LONG BEACH | K34: CA | N34: 90815 | O34: https://WWW.RHF.ORG | P34: 3340837 | Q34: 2000869 | R34: 59.9 | S34: 2740454 | T34: FRIENDSHIP HOUSE III, INC. IS A NOT-FOR-PROFIT CORPORATION FORMED IN ACCORDANCE WITH THE NOT-FOR-PROFIT STATUTES OF THE STATE OF INDIANA. THE CORPORATION WAS FORMED FOR THE PURPOSE OF OPERATING A 167 UNIT COMMUNITY KNOWN AS CROOKED CREEK TOWER, LOCATED IN INDIANAPOLIS, INDIANA, AND A 140 UNIT COMMUN | U34: {=MAX(_xlfn._xlws.FILTER('Email Outreach Prospects'!F:F, 'Email Outreach Prospects'!B:B=B34))} -> 0.2 | V34: P, S | W34: 2023 | X34: 310956562 | Y34: 10 | AB34: 1 | AC34: 0 | AD34: 0 | AE34: 0 | AF34: Uncertain
B35: MARIN AUDUBON SOCIETY | C35: 45973 | D35: 4159246057 | E35: BARBARA SALZMAN | F35: President | I35: PO BOX 599 | J35: MILL VALLEY | K35: CA | N35: 94942 | O35: https://WWW.MARINAUDUBON.ORG | P35: 1005699 | Q35: 926238 | R35: 92.1 | S35: 563461 | T35: THE MARIN AUDUBON SOCIETY IS DEDICATED TO ACTIVE PARTICIPATION IN CONSERVATION, ENVIRONMENTAL EDUCATION, AND ENJOYMENT OF OUR NATURAL HERITAGE. WE ADVOCATE SOUND LAND AND WATER RESOURCE PLANNING, AND ACT TO RESTORE, ENHANCE, AND SAFEGUARD OUR WETLANDS AND OTHER NATURAL HABITATS. BIRDS AND OTHER WILD | U35: {=MAX(_xlfn._xlws.FILTER('Email Outreach Prospects'!F:F, 'Email Outreach Prospects'!B:B=B35))} -> 40 | V35: A, B, C, E | W35: 2023 | X35: 946076664 | Y35: 10 | AB35: 1 | AC35: 0 | AD35: 0 | AE35: 0 | AF35: Uncertain
B36: Nihonmachi Little Friends | C36: 45973 | D36: 4159228898 | E36: Mokuau Dawn | F36: Chairperson | I36: 1830 Sutter Street | J36: San Francisco | K36: CA | N36: 94115 | O36: https://nlfchildcare.org | P36: 2842354 | Q36: 1667238 | R36: 58.7 | S36: 2537391 | T36: Nihonmachi Little Friends (NLF) is a Japanese bilingual multicultural & educational childcare organization. | U36: {=MAX(_xlfn._xlws.FILTER('Email Outreach Prospects'!F:F, 'Email Outreach Prospects'!B:B=B36))} -> 40 | V36: B | W36: 2023 | X36: 942325686 | Y36: 10 | Z36: Dawn | AB36: 0 | AC36: 1 | AD36: 1 | AE36: 0 | AF36: Uncertain | AG36: Nlfchildcare@gmail.com
B37: CODEPINK WOMEN FOR PEACE | C37: 45973 | D37: 3108273046 | E37: JODIE EVANS | F37: President | I37: 578 WASHINGTON BLVD 395 | J37: MARINA DEL REY | K37: CA | N37: 90292 | O37: https://www.codepink.org | P37: 1328143 | Q37: 1273425 | R37: 95.9 | S37: 1303424 | T37: TO END U.S. WARS AND MILITARISM, SUPPORT PEACE AND HUMAN RIGHTS INITIATIVES. | U37: {=MAX(_xlfn._xlws.FILTER('Email Outreach Prospects'!F:F, 'Email Outreach Prospects'!B:B=B37))} -> 40 | V37: B, E | W37: 2023 | X37: 262823386 | Y37: 10 | AB37: 1 | AC37: 0 | AD37: 0 | AE37: 0 | AF37: Uncertain
B38: CHRYSALIS CHARTER SCHOOL | C38: 45973 | D38: 5305479726 | E38: CATHERINE THOMPSON | F38: ADMINISTRATOR/ SUPERINTENDENT | I38: PO BOX 709 | J38: PALO CEDRO | K38: CA | N38: 96073 | O38: https://WWW.CHRYSALISCHARTERSCHOOL.COM | P38: 3363431 | Q38: 3294448 | R38: 97.9 | S38: 2991894 | T38: TO PROVIDE A PUBLIC EDUCATION WITH A SCIENCE AND NATURE EMPHASIS TO CHILDREN FROM TRANSITIONAL KINDERGARTEN THROUGH EIGHTH GRADE | U38: {=MAX(_xlfn._xlws.FILTER('Email Outreach Prospects'!F:F, 'Email Outreach Prospects'!B:B=B38))} -> 40 | V38: B, C, P | W38: 2023 | X38: 810569209 | Y38: 10 | Z38: Tim Drury | AB38: 0 | AC38: 1 | AD38: 1 | AE38: 0 | AF38: Uncertain | AG38: Talked to Catherine - she said I should email Tim Drury who's their administrative something or other. - timdrury@chrysalischarter.org. Also answered some questions about how they work: Teacher ran school- they have a teacher cooperative that decisions. development committee and another committee - someone onsite who does grants (parent volunteers who do the grant finding)
B39: FRIENDSHIP CIRCLE SD INC | C39: 45973 | D39: 4087555770 | E39: YOSEF RODAL | F39: Executive Dir. | I39: 441 SAXONY ROAD | J39: ENCINITAS | K39: CA | N39: 92024 | O39: https://www.friendshipsd.org | P39: 2690324 | Q39: 2531992 | R39: 94.1 | S39: 771056 | T39: to enrich the lives of children, teens and adults with special needs through social and recreational experiences and to inspire volunteers to participate in building a stronger and more inclusive community. | U39: {=MAX(_xlfn._xlws.FILTER('Email Outreach Prospects'!F:F, 'Email Outreach Prospects'!B:B=B39))} -> 25 | V39: P | W39: 2023 | X39: 203472700 | Y39: 10 | AB39: 1 | AC39: 0 | AD39: 0 | AE39: 0 | AF39: Uncertain
B40: BREAKTHROUGH SILICON VALLEY | C40: 45973 | D40: 4082876357 | E40: RAMON GARCIA-GOMEZ | F40: TREASURER | I40: 1635 PARK AVENUE | J40: SAN JOSE | K40: CA | N40: 951262123 | O40: https://WWW.BREAKTHROUGHSV.ORG | P40: 2246362 | Q40: 2189567 | R40: 97.5 | S40: 2924323 | T40: BREAKTHROUGH SILICON VALLEY PREPARES HIGHLY-MOTIVATED STUDENTS TO BECOME FIRST-GENERATION COLLEGE GRADUATES AND INSPIRES EMERGING LEADERS TO BE THE NEXT GENERATION OF EDUCATORS AND ADVOCATES FOR EQUITY. | U40: {=MAX(_xlfn._xlws.FILTER('Email Outreach Prospects'!F:F, 'Email Outreach Prospects'!B:B=B40))} -> 40 | V40: B | W40: 2023 | X40: 262168102 | Y40: 10 | Z40: Rebeca Duran | AB40: 1 | AC40: 1 | AD40: 0 | AE40: 0 | AF40: Uncertain | AG40: Talked to Vanessa - she said it would be best to talk to marisol or new executive director rebeca duran. She took my name, number, and email and a message so they can reach out
B41: THOMAS HOUSE TEMPORARY SHELTER | C41: 45973 | D41: 7145540357 | E41: SHAKOYA GREEN LONG | F41: CEO | I41: PO BOX 2737 | J41: GARDEN GROVE | K41: CA | N41: 928422737 | O41: https://WWW.THOMASHOUSESHELTER.ORG | P41: 1900870 | Q41: 1811413 | R41: 95.3 | S41: 1772001 | T41: TO PROVIDE A SAFE, SUPPORTIVE ENVIRONMENT AND RESOURCES NECESSARY FOR HOMELESS FAMILIES WITH CHILDREN TO REMAIN TOGETHER WHILE EMPOWERING THEM TO BECOME INDEPENDENT AND SELF-SUFFICIENT. TO KEEP AT RISK FAMILIES FROM BECOMING HOMELESS BY PROVIDING PREVENTION SERVICES INCLUDING RENTAL ASSISTANCE. | U41: {=MAX(_xlfn._xlws.FILTER('Email Outreach Prospects'!F:F, 'Email Outreach Prospects'!B:B=B41))} -> 40 | V41: C, P | W41: 2023 | X41: 330204757 | Y41: 10 | Z41: Shakoya | AB41: 1 | AC41: 1 | AD41: 1 | AE41: 0 | AF41: Uncertain | AG41: Talked to Angie - she said talk to the CEO, Shakoya. shakoya@thomashouseshelter.org - shoot her an email - set up a time to chat about it. Angie said she'd send her a message about it right now.
...

Sheet Foundations
B2: business name | C2: Contact Date | D2: phone | E2: Email | F2: website | G2: state | H2: EIN | I2: total assets | J2: grantee count | K2: cb grant count | L2: intermediary grant count | M2: paid officer count | N2: top officer name | O2: top officer title | P2: Column1 | Q2: Linkedin URL | R2: segment | S2: Sent VM | T2: Talked to Someone | U2: Send us an Email | V2: Reached Decision Maker | W2: Yes/No/Maybe/Uncertain | X2: Notes
B3: THE WILLIAM & FLORA HEWLETT FOUNDATION | C3: 46007 | D3: 6502344500 | F3: WWW.HEWLETT.ORG | G3: CA | I3: 13332174215 | J3: 1072 | K3: 1160 | L3: 71 | M3: 0 | N3: MARIANO-FLORENTINO CUELLAR | O3: CHAIR | P3: Foundation | R3: Intermediary Funders | W3: No Answer Try Again
B4: CONRAD N HILTON FOUNDATION | C4: 46007 | D4: 8188513724 | F4: WWW.HILTONFOUNDATION.ORG | G4: CA | I4: 7099706570 | J4: 976 | K4: 1057 | L4: 148 | M4: 1 | N4: PETER A LAUGHARN | O4: PRESIDENT AND CEO | P4: Foundation | R4: Intermediary Funders | W4: No Answer Try Again | X4: Michael@hilton
B5: THE CALIFORNIA WELLNESS FOUNDATION | C5: 46007 | D5: 8187021900 | F5: WWW.CALWELLNESS.ORG | G5: CA | I5: 1042135742 | J5: 738 | K5: 689 | L5: 49 | M5: 1 | N5: JUDY BELK | O5: PRESIDENT & CEO | P5: Foundation | R5: Intermediary Funders | W5: No Answer Try Again
B6: The James Irvine Foundation | C6: 46007 | D6: 4157772244 | F6: www.Irvine.org | G6: CA | I6: 3245582018 | J6: 628 | K6: 56 | L6: 36 | M6: 1 | N6: MELISSA LOPEZ | O6: PRESIDENT& CEO/DIR | P6: Foundation | R6: Intermediary Funders | W6: No Answer Try Again
B7: AARON'S FOUNDATION INC | D7: 678-402-3000 | E7: investorrelations@aarons.com | F7: https://www.aarons.com/aarons-gives | G7: =_xlfn.XLOOKUP(H7,Sheet2!B:B,Sheet2!D:D) -> GA | H7: 453611066 | I7: =_xlfn.XLOOKUP(H7,Sheet2!B:B,Sheet2!E:E) -> 201086 | J7: =_xlfn.XLOOKUP($H7,Sheet2!$B:$B,Sheet2!F:F) -> 128 | K7: =_xlfn.XLOOKUP($H7,Sheet2!$B:$B,Sheet2!G:G) -> 1 | L7: =_xlfn.XLOOKUP($H7,Sheet2!$B:$B,Sheet2!H:H) -> 10 | M7: =_xlfn.XLOOKUP($H7,Sheet2!$B:$B,Sheet2!I:I) -> 0 | N7: Rachel George | O7: Board Member / Senior Executive | P7: Foundation | Q7: https://www.linkedin.com/in/rachel-george-4b0a227/ | R7: =_xlfn.XLOOKUP(H7,Sheet2!B:B,Sheet2!N:N) -> Intermediary Funders
B8: Alaska Airlines Foundation | C8: 46008 | D8: 206-392-5719 | E8: Not publicly available | F8: https://www.alaskaair.com/content/about-us/social-responsibility/alaska-airlines-foundation | G8: =_xlfn.XLOOKUP(H8,Sheet2!B:B,Sheet2!D:D) -> AK | H8: 920166198 | I8: =_xlfn.XLOOKUP(H8,Sheet2!B:B,Sheet2!E:E) -> 10478825 | J8: =_xlfn.XLOOKUP($H8,Sheet2!$B:$B,Sheet2!F:F) -> 80 | K8: =_xlfn.XLOOKUP($H8,Sheet2!$B:$B,Sheet2!G:G) -> 1 | L8: =_xlfn.XLOOKUP($H8,Sheet2!$B:$B,Sheet2!H:H) -> 31 | M8: =_xlfn.XLOOKUP($H8,Sheet2!$B:$B,Sheet2!I:I) -> 0 | N8: Diana Birkett Rakow | O8: Chair of Board / SVP Public Affairs & Sustainability | P8: Foundation | Q8: https://www.linkedin.com/in/dianabirkettrakow/ | R8: =_xlfn.XLOOKUP(H8,Sheet2!B:B,Sheet2!N:N) -> Intermediary Funders | S8: 1 | X8: Bad number
B9: ALBERT AND ELAINE BORCHARD | C9: 46008 | D9: 8185651020 | E9: michael.spurgeon@borchardfoundation.org | F9: https://borchardfoundation.org | G9: =_xlfn.XLOOKUP(H9,Sheet2!B:B,Sheet2!D:D) -> CA | H9: 953294377 | I9: =_xlfn.XLOOKUP(H9,Sheet2!B:B,Sheet2!E:E) -> 18275989 | J9: =_xlfn.XLOOKUP($H9,Sheet2!$B:$B,Sheet2!F:F) -> 38 | K9: =_xlfn.XLOOKUP($H9,Sheet2!$B:$B,Sheet2!G:G) -> 36 | L9: =_xlfn.XLOOKUP($H9,Sheet2!$B:$B,Sheet2!H:H) -> 0 | M9: =_xlfn.XLOOKUP($H9,Sheet2!$B:$B,Sheet2!I:I) -> 2 | N9: Michael Spurgeon | O9: Executive Vice President / Director Center on Literary Arts | P9: Foundation | Q9: Not found | R9: =_xlfn.XLOOKUP(H9,Sheet2!B:B,Sheet2!N:N) -> California CB
B10: ALFRED P SLOAN FOUNDATION | C10: 46008 | D10: 212-649-1649 - ext 1676 | E10: Not publicly available | F10: https://sloan.org | G10: =_xlfn.XLOOKUP(H10,Sheet2!B:B,Sheet2!D:D) -> NY | H10: 131623877 | I10: =_xlfn.XLOOKUP(H10,Sheet2!B:B,Sheet2!E:E) -> 2116962267 | J10: =_xlfn.XLOOKUP($H10,Sheet2!$B:$B,Sheet2!F:F) -> 182 | K10: =_xlfn.XLOOKUP($H10,Sheet2!$B:$B,Sheet2!G:G) -> 0 | L10: =_xlfn.XLOOKUP($H10,Sheet2!$B:$B,Sheet2!H:H) -> 20 | M10: =_xlfn.XLOOKUP($H10,Sheet2!$B:$B,Sheet2!I:I) -> 2 | N10: Daniel L. Goroff | O10: Vice President & Program Director | P10: Foundation | Q10: Not found | R10: =_xlfn.XLOOKUP(H10,Sheet2!B:B,Sheet2!N:N) -> Intermediary Funders | S10: 1
B11: ALLETTA MORRIS MCBEAN CHARITABLE TRUST | C11: 46008 | D11: 760-564-3000 | E11: mcbeanproperties@att.net | F11: http://www.allettamcbeancharitabletrust.org | G11: =_xlfn.XLOOKUP(H11,Sheet2!B:B,Sheet2!D:D) -> CA | H11: 943019660 | I11: =_xlfn.XLOOKUP(H11,Sheet2!B:B,Sheet2!E:E) -> 20496407 | J11: =_xlfn.XLOOKUP($H11,Sheet2!$B:$B,Sheet2!F:F) -> 39 | K11: =_xlfn.XLOOKUP($H11,Sheet2!$B:$B,Sheet2!G:G) -> 4 | L11: =_xlfn.XLOOKUP($H11,Sheet2!$B:$B,Sheet2!H:H) -> 1 | M11: =_xlfn.XLOOKUP($H11,Sheet2!$B:$B,Sheet2!I:I) -> 0 | N11: Charlene C. Kleiner | O11: Administrator | P11: Foundation | Q11: Not found | R11: =_xlfn.XLOOKUP(H11,Sheet2!B:B,Sheet2!N:N) -> California CB | S11: 1
B12: ALLIANCE HEALTHCARE FOUNDATION | C12: 46008 | D12: 858-875-3305 | E12: barbara.valdivia@alliancehf.org | F12: https://alliancehf.org | G12: =_xlfn.XLOOKUP(H12,Sheet2!B:B,Sheet2!D:D) -> CA | H12: 330340635 | I12: =_xlfn.XLOOKUP(H12,Sheet2!B:B,Sheet2!E:E) -> 85505150 | J12: =_xlfn.XLOOKUP($H12,Sheet2!$B:$B,Sheet2!F:F) -> 68 | K12: =_xlfn.XLOOKUP($H12,Sheet2!$B:$B,Sheet2!G:G) -> 8 | L12: =_xlfn.XLOOKUP($H12,Sheet2!$B:$B,Sheet2!H:H) -> 0 | M12: =_xlfn.XLOOKUP($H12,Sheet2!$B:$B,Sheet2!I:I) -> 2 | N12: Barbara Orozco-Valdivia MPH | O12: Vice President of Programs & Community Partnerships | P12: Foundation | Q12: https://www.linkedin.com/in/barbaraorozcovaldivia/ | R12: =_xlfn.XLOOKUP(H12,Sheet2!B:B,Sheet2!N:N) -> California CB | S12: 1
B13: ALLY CHARITABLE FOUNDATION | D13: 980-312-8320 | E13: grants@ally.com | F13: https://ally.com/about/social-impact/grants/ | G13: =_xlfn.XLOOKUP(H13,Sheet2!B:B,Sheet2!D:D) -> NC | H13: 844571035 | I13: =_xlfn.XLOOKUP(H13,Sheet2!B:B,Sheet2!E:E) -> 81746335 | J13: =_xlfn.XLOOKUP($H13,Sheet2!$B:$B,Sheet2!F:F) -> 156 | K13: =_xlfn.XLOOKUP($H13,Sheet2!$B:$B,Sheet2!G:G) -> 6 | L13: =_xlfn.XLOOKUP($H13,Sheet2!$B:$B,Sheet2!H:H) -> 14 | M13: =_xlfn.XLOOKUP($H13,Sheet2!$B:$B,Sheet2!I:I) -> 0 | N13: Kathie Patterson | O13: Chair / Chief HR & Corporate Citizenship Officer | P13: Foundation | Q13: https://www.linkedin.com/in/kathie-patterson-9aaa058/ | R13: =_xlfn.XLOOKUP(H13,Sheet2!B:B,Sheet2!N:N) -> Intermediary Funders
B14: ALTMAN FOUNDATION | D14: 212-682-0970 | E14: info@altman.org | F14: https://www.altmanfoundation.org | G14: =_xlfn.XLOOKUP(H14,Sheet2!B:B,Sheet2!D:D) -> NY | H14: 131623879 | I14: =_xlfn.XLOOKUP(H14,Sheet2!B:B,Sheet2!E:E) -> 283326707 | J14: =_xlfn.XLOOKUP($H14,Sheet2!$B:$B,Sheet2!F:F) -> 150 | K14: =_xlfn.XLOOKUP($H14,Sheet2!$B:$B,Sheet2!G:G) -> 57 | L14: =_xlfn.XLOOKUP($H14,Sheet2!$B:$B,Sheet2!H:H) -> 22 | M14: =_xlfn.XLOOKUP($H14,Sheet2!$B:$B,Sheet2!I:I) -> 0 | N14: Deborah T. Velazquez | O14: President | P14: Foundation | Q14: Not found | R14: =_xlfn.XLOOKUP(H14,Sheet2!B:B,Sheet2!N:N) -> Intermediary Funders
B15: AMERICAN WOODMARK FOUNDATION INC | D15: 540-665-9100 | E15: Not publicly available | F15: https://americanwoodmark.com | G15: =_xlfn.XLOOKUP(H15,Sheet2!B:B,Sheet2!D:D) -> VA | H15: 541759773 | I15: =_xlfn.XLOOKUP(H15,Sheet2!B:B,Sheet2!E:E) -> 1278837 | J15: =_xlfn.XLOOKUP($H15,Sheet2!$B:$B,Sheet2!F:F) -> 260 | K15: =_xlfn.XLOOKUP($H15,Sheet2!$B:$B,Sheet2!G:G) -> 7 | L15: =_xlfn.XLOOKUP($H15,Sheet2!$B:$B,Sheet2!H:H) -> 20 | M15: =_xlfn.XLOOKUP($H15,Sheet2!$B:$B,Sheet2!I:I) -> 0 | N15: Brenda Dupont | O15: Chair / Executive Assistant to CEO | P15: Foundation | Q15: https://www.linkedin.com/in/brenda-dupont-38a45533 | R15: =_xlfn.XLOOKUP(H15,Sheet2!B:B,Sheet2!N:N) -> Intermediary Funders
B16: ANN JACKSON FAMILY FOUNDATION | C16: 46008 | D16: 805-969-2258 | E16: palmer.jackson@gmail.com | F16: https://www.annjacksonfamilyfoundation.org | G16: =_xlfn.XLOOKUP(H16,Sheet2!B:B,Sheet2!D:D) -> CA | H16: 953367511 | I16: =_xlfn.XLOOKUP(H16,Sheet2!B:B,Sheet2!E:E) -> 88737372 | J16: =_xlfn.XLOOKUP($H16,Sheet2!$B:$B,Sheet2!F:F) -> 98 | K16: =_xlfn.XLOOKUP($H16,Sheet2!$B:$B,Sheet2!G:G) -> 372 | L16: =_xlfn.XLOOKUP($H16,Sheet2!$B:$B,Sheet2!H:H) -> 0 | M16: =_xlfn.XLOOKUP($H16,Sheet2!$B:$B,Sheet2!I:I) -> 0 | N16: Palmer G. Jackson Jr. | O16: President / Managing Trustee | P16: Foundation | Q16: https://www.linkedin.com/in/palmerjackson/ | R16: =_xlfn.XLOOKUP(H16,Sheet2!B:B,Sheet2!N:N) -> California CB | S16: 1
B17: Whitier Trust | C17: 46008 | D17: 626-441-5188 | E17: Not publicly available | F17: None | G17: =_xlfn.XLOOKUP(H17,Sheet2!B:B,Sheet2!D:D) -> CA | H17: 952114455 | I17: =_xlfn.XLOOKUP(H17,Sheet2!B:B,Sheet2!E:E) -> 42771908 | J17: =_xlfn.XLOOKUP($H17,Sheet2!$B:$B,Sheet2!F:F) -> 30 | K17: =_xlfn.XLOOKUP($H17,Sheet2!$B:$B,Sheet2!G:G) -> 44 | L17: =_xlfn.XLOOKUP($H17,Sheet2!$B:$B,Sheet2!H:H) -> 0 | M17: =_xlfn.XLOOKUP($H17,Sheet2!$B:$B,Sheet2!I:I) -> 1 | N17: Pegine E. Grayson | O17: Executive Director / Secretary | P17: Foundation Management | Q17: Not found | R17: =_xlfn.XLOOKUP(H17,Sheet2!B:B,Sheet2!N:N) -> California CB | X17: Pegine said this sounds great and that I should send a write up of what we're doing (2-3) pages to Jesse ostroff. - notes from calls: 12 people on team. Send it to her and she can share it and they can say this is a great resource. And send it to all the foundations they’re over. The foundations can determine which clients need to diversify and give them capacity building grants so they can use our service. Send email to Jesse ostraf Jostroff@whitiertrust.com We had a brief conversation and that she suggested I reach ut to him because its possible for clients who want capacity building their grantees
B18: Anschutz Family Foundation | D18: 303-293-2338 | E18: abel@anschutzfamily.org | F18: https://anschutzfamilyfoundation.org | G18: =_xlfn.XLOOKUP(H18,Sheet2!B:B,Sheet2!D:D) -> CO | H18: 742132676 | I18: =_xlfn.XLOOKUP(H18,Sheet2!B:B,Sheet2!E:E) -> 45765575 | J18: =_xlfn.XLOOKUP($H18,Sheet2!$B:$B,Sheet2!F:F) -> 160 | K18: =_xlfn.XLOOKUP($H18,Sheet2!$B:$B,Sheet2!G:G) -> 236 | L18: =_xlfn.XLOOKUP($H18,Sheet2!$B:$B,Sheet2!H:H) -> 13 | M18: =_xlfn.XLOOKUP($H18,Sheet2!$B:$B,Sheet2!I:I) -> 0 | N18: Abel Wurmnest | O18: Executive Director | P18: Foundation | Q18: https://www.linkedin.com/in/abel-wurmnest-06359916 | R18: =_xlfn.XLOOKUP(H18,Sheet2!B:B,Sheet2!N:N) -> Intermediary Funders
B19: ARCONIC CHARITABLE FOUNDATION II | D19: 412-315-2984 | E19: ryan.kish@arconic.com | F19: https://www.arconic.com/foundation | G19: =_xlfn.XLOOKUP(H19,Sheet2!B:B,Sheet2!D:D) -> PA | H19: 843049720 | I19: =_xlfn.XLOOKUP(H19,Sheet2!B:B,Sheet2!E:E) -> 0 | J19: =_xlfn.XLOOKUP($H19,Sheet2!$B:$B,Sheet2!F:F) -> 82 | K19: =_xlfn.XLOOKUP($H19,Sheet2!$B:$B,Sheet2!G:G) -> 4 | L19: =_xlfn.XLOOKUP($H19,Sheet2!$B:$B,Sheet2!H:H) -> 11 | M19: =_xlfn.XLOOKUP($H19,Sheet2!$B:$B,Sheet2!I:I) -> 0 | N19: Ryan Kish | O19: President and Treasurer | P19: Foundation | Q19: https://www.linkedin.com/in/ryankish/ | R19: =_xlfn.XLOOKUP(H19,Sheet2!B:B,Sheet2!N:N) -> Intermediary Funders
B20: ARCUS FOUNDATION | D20: 212-488-3000 | E20: hantonissen@arcusfoundation.org | F20: https://www.arcusfoundation.org | G20: =_xlfn.XLOOKUP(H20,Sheet2!B:B,Sheet2!D:D) -> NY | H20: 383332791 | I20: =_xlfn.XLOOKUP(H20,Sheet2!B:B,Sheet2!E:E) -> 275369766 | J20: =_xlfn.XLOOKUP($H20,Sheet2!$B:$B,Sheet2!F:F) -> 168 | K20: =_xlfn.XLOOKUP($H20,Sheet2!$B:$B,Sheet2!G:G) -> 437 | L20: =_xlfn.XLOOKUP($H20,Sheet2!$B:$B,Sheet2!H:H) -> 30 | M20: =_xlfn.XLOOKUP($H20,Sheet2!$B:$B,Sheet2!I:I) -> 0 | N20: Annette Lanjouw | O20: Chief Executive Officer | P20: Foundation | Q20: https://www.linkedin.com/in/annette-lanjouw-1a959ab/ | R20: =_xlfn.XLOOKUP(H20,Sheet2!B:B,Sheet2!N:N) -> Intermediary Funders
B21: AVANGRID FOUNDATION INC | D21: 203-836-6457 | E21: avangridfoundation@avangrid.com | F21: https://www.avangrid.com/avangrid-foundation | G21: =_xlfn.XLOOKUP(H21,Sheet2!B:B,Sheet2!D:D) -> CT | H21: 134200689 | I21: =_xlfn.XLOOKUP(H21,Sheet2!B:B,Sheet2!E:E) -> 5760467 | J21: =_xlfn.XLOOKUP($H21,Sheet2!$B:$B,Sheet2!F:F) -> 64 | K21: =_xlfn.XLOOKUP($H21,Sheet2!$B:$B,Sheet2!G:G) -> 0 | L21: =_xlfn.XLOOKUP($H21,Sheet2!$B:$B,Sheet2!H:H) -> 32 | M21: =_xlfn.XLOOKUP($H21,Sheet2!$B:$B,Sheet2!I:I) -> 0 | N21: Pablo Colon | O21: Director Corporate Citizenship / Executive Director | P21: Foundation | Q21: Not found | R21: =_xlfn.XLOOKUP(H21,Sheet2!B:B,Sheet2!N:N) -> Intermediary Funders
B22: BALL BROTHERS FOUNDATION | D22: 765-741-5500 | E22: info@ballfdn.org | F22: https://www.ballfdn.org | G22: =_xlfn.XLOOKUP(H22,Sheet2!B:B,Sheet2!D:D) -> IN | H22: 350882856 | I22: =_xlfn.XLOOKUP(H22,Sheet2!B:B,Sheet2!E:E) -> 170691544 | J22: =_xlfn.XLOOKUP($H22,Sheet2!$B:$B,Sheet2!F:F) -> 59 | K22: =_xlfn.XLOOKUP($H22,Sheet2!$B:$B,Sheet2!G:G) -> 18 | L22: =_xlfn.XLOOKUP($H22,Sheet2!$B:$B,Sheet2!H:H) -> 17 | M22: =_xlfn.XLOOKUP($H22,Sheet2!$B:$B,Sheet2!I:I) -> 0 | N22: Jud Fisher | O22: President and CEO | P22: Foundation | Q22: Not found | R22: =_xlfn.XLOOKUP(H22,Sheet2!B:B,Sheet2!N:N) -> Intermediary Funders
B23: BANK OF GREENE COUNTY | D23: 518-943-1424 | E23: amandakg@tbogc.com | F23: https://www.thebankofgreenecounty.com | G23: =_xlfn.XLOOKUP(H23,Sheet2!B:B,Sheet2!D:D) -> NY | H23: 141810419 | I23: =_xlfn.XLOOKUP(H23,Sheet2!B:B,Sheet2!E:E) -> 11848394 | J23: =_xlfn.XLOOKUP($H23,Sheet2!$B:$B,Sheet2!F:F) -> 190 | K23: =_xlfn.XLOOKUP($H23,Sheet2!$B:$B,Sheet2!G:G) -> 6 | L23: =_xlfn.XLOOKUP($H23,Sheet2!$B:$B,Sheet2!H:H) -> 10 | M23: =_xlfn.XLOOKUP($H23,Sheet2!$B:$B,Sheet2!I:I) -> 0 | N23: Amanda Grant | O23: Charitable Foundation Contact | P23: Foundation | Q23: Not found | R23: =_xlfn.XLOOKUP(H23,Sheet2!B:B,Sheet2!N:N) -> Intermediary Funders
B24: BARSTOW FOUNDATION | D24: 989-839-5305 | E24: Not found | F24: None | G24: =_xlfn.XLOOKUP(H24,Sheet2!B:B,Sheet2!D:D) -> CA | H24: 386151026 | I24: =_xlfn.XLOOKUP(H24,Sheet2!B:B,Sheet2!E:E) -> 5545120 | J24: =_xlfn.XLOOKUP($H24,Sheet2!$B:$B,Sheet2!F:F) -> 40 | K24: =_xlfn.XLOOKUP($H24,Sheet2!$B:$B,Sheet2!G:G) -> 84 | L24: =_xlfn.XLOOKUP($H24,Sheet2!$B:$B,Sheet2!H:H) -> 0 | M24: =_xlfn.XLOOKUP($H24,Sheet2!$B:$B,Sheet2!I:I) -> 1 | N24: John E. Kessler | O24: EVP/Senior Trust Officer (Former) | P24: Foundation | Q24: Not found | R24: =_xlfn.XLOOKUP(H24,Sheet2!B:B,Sheet2!N:N) -> California CB
B25: BCM Foundation | D25: 562-696-0338 | E25: Use contact form | F25: https://bcm-foundation.org | G25: =_xlfn.XLOOKUP(H25,Sheet2!B:B,Sheet2!D:D) -> CA | H25: 262667384 | I25: =_xlfn.XLOOKUP(H25,Sheet2!B:B,Sheet2!E:E) -> 53348657 | J25: =_xlfn.XLOOKUP($H25,Sheet2!$B:$B,Sheet2!F:F) -> 24 | K25: =_xlfn.XLOOKUP($H25,Sheet2!$B:$B,Sheet2!G:G) -> 12 | L25: =_xlfn.XLOOKUP($H25,Sheet2!$B:$B,Sheet2!H:H) -> 0 | M25: =_xlfn.XLOOKUP($H25,Sheet2!$B:$B,Sheet2!I:I) -> 1 | N25: James D. Shepard | O25: Trustee / Managing Director | P25: Foundation | Q25: Not found | R25: =_xlfn.XLOOKUP(H25,Sheet2!B:B,Sheet2!N:N) -> California CB
B26: BELLA VISTA FOUNDATION | D26: 415-561-6540 | E26: ejohansson@pfs-llc.net | F26: https://www.bellavistafoundation.org | G26: =_xlfn.XLOOKUP(H26,Sheet2!B:B,Sheet2!D:D) -> CA | H26: 943345967 | I26: =_xlfn.XLOOKUP(H26,Sheet2!B:B,Sheet2!E:E) -> 68423844 | J26: =_xlfn.XLOOKUP($H26,Sheet2!$B:$B,Sheet2!F:F) -> 88 | K26: =_xlfn.XLOOKUP($H26,Sheet2!$B:$B,Sheet2!G:G) -> 17 | L26: =_xlfn.XLOOKUP($H26,Sheet2!$B:$B,Sheet2!H:H) -> 6 | M26: =_xlfn.XLOOKUP($H26,Sheet2!$B:$B,Sheet2!I:I) -> 0 | N26: Emily Johansson | O26: Program Director / Co-Executive Director | P26: Foundation | Q26: https://www.linkedin.com/in/emily-johansson-8043251 | R26: =_xlfn.XLOOKUP(H26,Sheet2!B:B,Sheet2!N:N) -> California CB
B27: BERKSHIRE BANK FOUNDATION INC | D27: 413-447-1722 | E27: foundation@berkshirebank.com | F27: https://www.berkshirebank.com/about-us/our-impact/community-support/berkshire-bank-foundation | G27: =_xlfn.XLOOKUP(H27,Sheet2!B:B,Sheet2!D:D) -> MA | H27: 43365869 | I27: =_xlfn.XLOOKUP(H27,Sheet2!B:B,Sheet2!E:E) -> 18644149 | J27: =_xlfn.XLOOKUP($H27,Sheet2!$B:$B,Sheet2!F:F) -> 203 | K27: =_xlfn.XLOOKUP($H27,Sheet2!$B:$B,Sheet2!G:G) -> 16 | L27: =_xlfn.XLOOKUP($H27,Sheet2!$B:$B,Sheet2!H:H) -> 19 | M27: =_xlfn.XLOOKUP($H27,Sheet2!$B:$B,Sheet2!I:I) -> 0 | N27: Lori Gazzillo Kiely | O27: Managing Director / Foundation Director | P27: Foundation | Q27: https://www.linkedin.com/in/lori-gazzillo-kiely-8291174 | R27: =_xlfn.XLOOKUP(H27,Sheet2!B:B,Sheet2!N:N) -> Intermediary Funders
B28: BESS J HODGES FOUNDATION | D28: 562-961-4115 | E28: Not found | F28: None | G28: =_xlfn.XLOOKUP(H28,Sheet2!B:B,Sheet2!D:D) -> CA | H28: 330046140 | I28: =_xlfn.XLOOKUP(H28,Sheet2!B:B,Sheet2!E:E) -> 6370611 | J28: =_xlfn.XLOOKUP($H28,Sheet2!$B:$B,Sheet2!F:F) -> 35 | K28: =_xlfn.XLOOKUP($H28,Sheet2!$B:$B,Sheet2!G:G) -> 215 | L28: =_xlfn.XLOOKUP($H28,Sheet2!$B:$B,Sheet2!H:H) -> 0 | M28: =_xlfn.XLOOKUP($H28,Sheet2!$B:$B,Sheet2!I:I) -> 2 | N28: George Murchison | O28: Executive Director | P28: Foundation | Q28: Not found | R28: =_xlfn.XLOOKUP(H28,Sheet2!B:B,Sheet2!N:N) -> California CB
B29: BISSELL Pet Foundation | D29: 616-735-6666 | E29: info@bissellpetfoundation.org | F29: https://www.bissellpetfoundation.org | G29: =_xlfn.XLOOKUP(H29,Sheet2!B:B,Sheet2!D:D) -> MI | H29: 383853264 | I29: =_xlfn.XLOOKUP(H29,Sheet2!B:B,Sheet2!E:E) -> 4578467 | J29: =_xlfn.XLOOKUP($H29,Sheet2!$B:$B,Sheet2!F:F) -> 229 | K29: =_xlfn.XLOOKUP($H29,Sheet2!$B:$B,Sheet2!G:G) -> 0 | L29: =_xlfn.XLOOKUP($H29,Sheet2!$B:$B,Sheet2!H:H) -> 12 | M29: =_xlfn.XLOOKUP($H29,Sheet2!$B:$B,Sheet2!I:I) -> 0 | N29: Emma Allen (Geers) | O29: Associate Grants and Programs Manager | P29: Foundation | Q29: https://www.linkedin.com/in/emma-allen-geers-a588abb6 | R29: =_xlfn.XLOOKUP(H29,Sheet2!B:B,Sheet2!N:N) -> Intermediary Funders
... B106: Public Welfare Foundation Inc | D106: (202) 965-1800 | E106: info@publicwelfare.org | F106: https://www.publicwelfare.org | G106: =_xlfn.XLOOKUP(H106,Sheet2!B:B,Sheet2!D:D) -> DC | H106: 540597601 | I106: =_xlfn.XLOOKUP(H106,Sheet2!B:B,Sheet2!E:E) -> 601086862 | J106: =_xlfn.XLOOKUP($H106,Sheet2!$B:$B,Sheet2!F:F) -> 166 | K106: =_xlfn.XLOOKUP($H106,Sheet2!$B:$B,Sheet2!G:G) -> 11 | L106: =_xlfn.XLOOKUP($H106,Sheet2!$B:$B,Sheet2!H:H) -> 11 | M106: =_xlfn.XLOOKUP($H106,Sheet2!$B:$B,Sheet2!I:I) -> 5 | N106: Thena Robinson Mock | O106: Vice President of Programs | P106: Foundation | Q106: https://www.linkedin.com/in/thena-robinsonmock | R106: =_xlfn.XLOOKUP(H106,Sheet2!B:B,Sheet2!N:N) -> Intermediary Funders
B107: BlueStone Services | D107: 888-797-2583 | F107: bluestonesvc.com | N107: Trey Gailey CPA | O107: Managing Director | P107: Foundation Management
B108: Crewe Foundation Services | D108: (385) 322-3400 | F108: crewefoundationservices.com | N108: Don Evans | O108: President and CEO | P108: Foundation Management
B109: Foundation Group | F109: 501c3.org | N109: Greg McRay EA | O109: President and CEO | P109: Foundation Management
B110: Foundation Source | F110: foundationsource.com | N110: Elizabeth Wong | O110: Head of Philanthropic Advisory Services | P110: Foundation Management
B111: Pacific Foundation Services | F111: pfs-llc.net | N111: Juliana Grenzeback | O111: President | P111: Foundation Management
B112: Sterling Foundation Management | D112: 703-437-9720 | F112: sterlingfoundations.com | N112: Roger D. Silk PhD | O112: Founder and CEO | P112: Foundation Management
B113: Arden Trust Company | F113: ardentrust.com | N113: Michael Roberts | O113: President | P113: Foundation Management
B114: Bessemer Trust | F114: bessemertrust.com | N114: Caroline Woodruff Hodkinson | O114: Managing Director Head of Philanthropy | P114: Foundation Management
