Workbook

Sheet Calls
B2: Org | C2: Priority | D2: Date Contacted | E2: Phone | F2: Contact | G2: Title | H2: Email | I2: State | J2: Timezone | K2: Dependents | L2: EIN | M2: Rating | N2: Website | O2: About | P2: Sunsetting | Q2: Segment | R2: Org Type | S2: Outcome | T2: Call Notes
B3: ERB FAMILY FOUNDATION | C3: 200 | D3: 46029 | E3: 248-498-2503 | F3: Tara Tuomaala | G3: Vice President of Programs | H3: ttuomaala@erbff.org | I3: MI | J3: #N/A | K3: 0 | L3: 205966333 | M3: 1.5 Sunsetting | O3: SE Michigan/Detroit focus. Funds arts/culture, democracy, sustainable business. Full staff with direct emails. Spending down by 2034 - grantees need help. | P3: 2034 | R3: Foundation | S3: 5. Interested | T3: 1/7 - VM 1/9 - Tara tuomaala at Erb Family Foundation called back – she said they do give out capacity building grant service things and that I can send info and she’d have people take a look at it. Then I asked if I could share what we do. She asked some great questions like: What size nonprofit 500K-2M (or bigger if they have regional offices) - What type of nonprofito Education, health, art- Geographically specific? o Yes, lots of smaller nonprofits who could benefit from local partnerships - How is it different from Candid(I think that’s what it’s called) where someone does research o Predictive modeling and time saved doing research...I also told her about the pilot idea and sending a list of who we recommend they offer it to as well as the price point (she seemed completely unquestionably unphased)..She said to send the stuff and I said I’d send the one pager, the example report, and the list of nonprofits we recommend should use our service 2/9 - called, left VM. Sent follow up email
B4: VetsBoats | C4: =_xlfn.XLOOKUP(Table1[[#This Row],[EIN]],Sheet5!#REF!,Sheet5!#REF!) -> #REF! | D4: 46029 | E4: 720.473.3844 | F4: Matt Goettelman | H4: matt.goettelman@vetsboats.org | I4: CA | J4: Pacific | R4: Nonprofit | S4: 5. Interested | T4: 1/7 - Alec requested Matt complete a questionnaire and submit payment to receive a first report by January 1st. Matt confirmed he would complete the questionnaire and submit payment information later that night. Alec confirmed receiving the survey but noted payment had not processed, then Matt requested a sample report before committing to annual billing.
B5: Aspiriant | D5: 46027 | E5: 650 305 3481 | F5: Talia Pierluissi | G5: Director - Wealth Management | I5: CA | J5: Pacific | M5: 1. Excellent | O5: Ex-Stanford dev | Q5: Foundation Management | R5: MFO | S5: 4. Reached Decision Maker | T5: 1/5 - Connected to her VM, she called back and gave her email. I sent her an email about what we do asking to meet. tpierluissi@aspiriant.com 1/7 - Called, left voicemail -- Need to send list of foundation recommendatins like i did with Jesse 2/9 - Called, left VM, sent follow up text - she responded and said that she's not involved in this type of work
B6: Mt Sinai Health Care Foundation | D6: 46027 | E6: (216) 421-5500 | F6: Mitch Balk | G6: President | I6: OH | J6: 0 | O6: Improving health and well being of Jewish and general communities in Cleveland. | Q6: Nonprofit | R6: Foundation | S6: 4. Reached Decision Maker | T6: 1/5 - Told me their actually a foundation and that they do capacity building 1/7 - Called, was in meeting. Do some research on them and then call back. 1/9 - Called, didn't give me the option to leave a VM
B7: THE COLLINS FOUNDATION | D7: 46029 | E7: 503-227-7171 | F7: Kymberli Contreras | G7: Executive Administrator | H7: kcontreras@collinsfoundation.org | J7: Pacific | K7: 200 | L7: 936021893 | M7: 1.Excellent | O7: 50 Oregon community nonprofits. $10M/year grantmaking. $310M+ awarded since 1947. Professional staff with direct contact. | R7: Foundation | S7: 4. Reached Decision Maker | T7: 1/7 - She thought I wanted to be their data guy, then she thought I was tech, then she understood what I was saying and said send a one pager (though they just did the budget and she wasn't sure how much they have ) she gets back into town next week (is gone the rest of this week) 1/9 - left VM (her extension is 1014), Sent email
B8: THE DYSON FOUNDATION | C8: =_xlfn.XLOOKUP(Table1[[#This Row],[EIN]],Sheet5!#REF!,Sheet5!#REF!) -> #REF! | D8: 46029 | E8: 845-790-6321 | F8: Andrea L. Reynolds | G8: Director of Programs | H8: cstancell@dyson.org | I8: NY | J8: Eastern | K8: 36 | L8: 136084888 | M8: 1.Excellent | O8: CEO: Andrea L. Reynolds areynolds@dyson.org 845-790-6321. Program Officers: Jennifer Drake jdrake@dyson.org, Jennifer Killian jkillian@dyson.org. 25 Halcyon Road, Millbrook, NY 12545. General: 845-677-0644. | R8: Foundation | S8: 4. Reached Decision Maker | T8: 1/7 - Left VM 1/8 - Andrea called back. She said she wasn't sure this would be something they would do for their grantees but if their grantees approached them asking for it then they'd consider it that way. I asked if she would mind looking through a list of grantees they have who might benefit and share her thoughts on if it would actually be helpful or not (pushed that the feedback itself is super helpful) she said sure. She also mentioned that a problem they have is that they get applications from people that are totally unqualified and it wastes their time. I askwed if I could share what we do and she said no just send it in the email. I said I'd put it in the email and call back in a week. 1/9 - Left VM
B9: The William & Flora Hewlett Foundation | D9: 46027 | E9: (650) 234-4500 ext 4769 | F9: Jennifer Wei | G9: Director, Effective Philanthropy Group | I9: CA | J9: Pacific | L9: 941655673 | M9: 2. Good | N9: https://hewlett.org/about-us/people/ | O9: Portland, OR; Oregon-focused grantmaking | Q9: Foundation | R9: Foundation | S9: 4. Reached Decision Maker | T9: 1/5 - She thought I was calling to tell her that her raising Cane's order was ready. she said she want sure because they don't have open applications. I told her it was actually so that their nonprofits could find other foundations and become less dependent just in them. she gave me her email and said to shoot over the info 1/7 - Called, no answer and no option for VM 1/8 - Hi Alec, Thank you for the follow-up information – it’s helpful to see the summary info as well as the sample report. I appreciate what you’re doing to help the nonprofit sector especially during a time of significant government funding cuts! We are not in a position to make any new investments at this time as our funds are already allocated for the year, but I’ve shared this with some colleagues to put on their radars. I’d be interested to hear how you’re doing later this year – perhaps check back in the summer or fall. Thanks again for reaching out! Best, Jennifer
B10: Whittier Trust | D10: 46027 | E10: 626-441-5111 | F10: Jesse Ostroff | G10: VP - Philanthropic Services | I10: CA | J10: #N/A | M10: 1.Excellent | O10: YOUR CONTACT | Q10: Foundation Management | R10: MFO | S10: 4. Reached Decision Maker | T10: 12/23 - He said it sounded interesting and liked that it would encourage nonprofits to reach out to more applicable foundations (sounds like they get a lot of random applicants who don't qualify. Sent one pager and sample report 1/7 - Called left VM 1/9 - Called left VM
C11: =_xlfn.XLOOKUP(Table1[[#This Row],[EIN]],Sheet5!#REF!,Sheet5!#REF!) -> #REF! | D11: 46027 | F11: Bri | G11: Owner | S11: 4. Reached Decision Maker
B12: BBR Partners | D12: 46027 | E12: 212-313-9870 | F12: Stephanie Diamond | G12: Director of Strategic Philanthropy | I12: NY | J12: 0 | O12: Ex-Schwab Charitable | Q12: Foundation Management | R12: MFO | S12: 3. Talked to Someone | T12: She said she'd let Stephanie know I called
B13: Chilton Trust | D13: 46027 | E13: 212-843-6882 | F13: David Hamar (Hey mar) | G13: Philanthropy Advisory | I13: NY | J13: 0 | O13: 96% capacity grants! | Q13: Foundation Management | R13: MFO | S13: 3. Talked to Someone | T13: She said if I don't have a name she won't connect me with someone but she took a message
B14: El Pomar Foundation | D14: 46027 | E14: (719) 633-7733 | F14: Matt Carpenter | G14: EVP & COO | I14: CO | J14: #N/A | L14: 846002373 | M14: 2. Good | N14: https://elpomar.org/about-us/leadership/ | O14: President: Tonya Allen; ~70 staff; Stephanie Duffy (Dir. Grants & Program Ops) | Q14: Foundation | R14: Foundation | S14: 3. Talked to Someone | T14: Reached Ellen P. who may be the secretary for Matt Carpenter. she gave me an email so I can send her our blurb and then she'd see if Matt's the right guy to talk to Ellenp20@elpomar.org
B15: HEADWATERS HEALTH FOUNDATION | C15: =_xlfn.XLOOKUP(Table1[[#This Row],[EIN]],Sheet5!#REF!,Sheet5!#REF!) -> #REF! | D15: 46031 | E15: (406) 926-6526 | F15: Erin Switalski | G15: Staff (Program Leadership) | I15: MT | J15: Mountain | K15: 29 | L15: 811099715 | M15: 1.Excellent | O15: 20+ years nonprofit experience. Montana/human rights/housing/environmental health. Founding CEO Brenda Solorzano left to lead CA Endowment. 725 W Central Ave Ste 210, Missoula MT 59801. | R15: Foundation | S15: 3. Talked to Someone
B16: Kashif Incubator | D16: 46027 | E16: (917) 282-1903 | F16: Chanelle Elaine | G16: President | I16: NY | J16: 0 | O16: Original pathways into filmmaking through equity-access practices. | Q16: Nonprofit | R16: Nonprofit | S16: 3. Talked to Someone | T16: Veronicas personal cell. call her next week(they're off this week) she didn't seem to mind that I accidentally called her cell
B17: O.L. Halsell Foundation | D17: 46027 | F17: W. David Stauffer Jr. | G17: President | H17: mroach@ncousa.com | I17: CA | J17: #N/A | L17: 956027266 | M17: 2. Good | R17: Foundation | S17: 3. Talked to Someone | T17: Email is from their CPA and is for Morgan Roach
B18: Oxford Financial | D18: 46027 | E18: 317-843-5678 | F18: Michele Hargis CAP | G18: Managing Director | I18: IN | J18: 0 | O18: CAP designation | Q18: Foundation Management | R18: MFO | S18: 3. Talked to Someone | T18: She's not involved in that and said to call back after 3:30 and she can find out who the right person is to talk to.
B19: PRICE PHILANTHROPIES FOUNDATION | C19: =_xlfn.XLOOKUP(Table1[[#This Row],[EIN]],Sheet5!#REF!,Sheet5!#REF!) -> #REF! | D19: 46031 | E19: (619) 795-2000 | F19: Sakara Tear | G19: Senior Director of Community Initiatives | H19: stear@pricephilanthropies.org | I19: CA | J19: Pacific | K19: 36 | L19: 465129465 | M19: 1.Excellent | O19: 93% capacity; grantees are small City Heights nonprofits who need funding diversification | R19: Foundation | S19: 3. Talked to Someone | T19: ckam@pricephilanthropies.org - talked to Christina and she took a message for Sakara and gave me her email so I can forward a little shpeal about us.
B20: Seven Acres Foundation | D20: 46027 | E20: (509) 670-9058 | F20: Maribel Cruz | G20: Executive Director | I20: WA | J20: #N/A | O20: Fund and construct the Community Center at Lake Chelan. | Q20: Nonprofit | R20: Nonproft | S20: 3. Talked to Someone | T20: Shoot her an email at maribel@chelancommunity.org-Ben 1/9 - called, apparently the number goes to Bens personal cell. He told me to email Maribel
B21: THE RALPH C WILSON JR FOUNDATION | C21: =_xlfn.XLOOKUP(Table1[[#This Row],[EIN]],Sheet5!#REF!,Sheet5!#REF!) -> #REF! | E21: 313-885-1895 | F21: Amber Slichta | G21: Vice President of Programs | H21: info@rcwjrf.org | I21: MI | J21: #N/A | K21: 63 | L21: 450921232 | M21: 1.Excellent | O21: Also: David Egner (President/CEO), Maura Dewan (VP Programs & Corporate Affairs), Jim Boyle (VP Programs & Strategy). 27 full-time staff. $1.2B over 20 years expiring Jan 2035. Focus: SE Michigan and Western NY. | P21: Sunsetting | R21: Foundation | S21: 3. Talked to Someone | T21: Taked to Maria (Suchyta?) She said they're a spend down foundation ending at the end of 2038. I mentioned it could be helpful for their grantees so they can get funding after their gone. She got my info and said to send more info
B22: THE ROUNDHOUSE FOUNDATION | D22: 46029 | E22: 541-904-0700 | F22: Erin Borla | G22: Executive Director & Trustee | H22: emily@roundhousefoundation.org | J22: Pacific | K22: 91 | L22: 226930631 | M22: 1.Excellent | O22: 91 dependent grantees (rural Oregon nonprofits). 6 CB service grants including strategic planning and technical assistance. Professional staff with direct emails on website. | R22: Foundation | S22: 3. Talked to Someone | T22: Talked to Emily, she said I put it simply and had me send an email.
B23: Acton School of Business | D23: 46027 | E23: (512) 695-2954 | F23: Chris Coggin | G23: President/CEO | I23: TX | J23: #N/A | K23: 0 | O23: Preparing entrepreneurs and world changers ages 6-66 using learner-driven approach. | Q23: Nonprofit | R23: Education | S23: 2. VM
B24: AlTi Tiedemann | D24: 46027 | E24: 212-396-5900 | F24: Jill Shipley | G24: Managing Director | I24: NY | J24: #N/A | K24: 0 | O24: Philanthropy curriculum | Q24: Foundation Management | R24: MFO | S24: 2. VM
B25: Ann Jackson Family Foundation | D25: 46027 | E25: (805) 969-2258 | F25: Palmer Jackson Jr. | G25: Managing Trustee | H25: palmer.jackson@gmail.com | I25: CA | J25: #N/A | L25: 953367511 | M25: 1. Excellent | O25: Santa Barbara based | S25: 2. VM
B26: Aspen Art Museum Foundation | D26: 46027 | E26: (970) 925-8050 | F26: Nicola Lees | G26: Artistic Director and CEO | I26: CO | J26: 0 | O26: Endowment fund for Aspen Art Museum. | Q26: Nonprofit | R26: Arts & Culture | S26: 2. VM
B27: Bay Education Fund | D27: 46027 | E27: (650) 204-0575 | F27: Tammy Crown | G27: President | I27: CA | J27: 0 | O27: Community investment fund transforming district capacity with families and teachers. | Q27: Nonprofit | R27: Education | S27: 2. VM
B28: Better Angels United | D28: 46027 | E28: (213) 293-6950 | F28: Adam Miller | G28: Director/President | I28: CA | J28: 0 | O28: Holistic approach to tackling homelessness in Los Angeles. | Q28: Nonprofit | R28: Human Services | S28: 2. VM
B29: Brown Brothers Harriman | D29: 46027 | E29: 212-483-1818 | F29: Drew Rabe | G29: MD - Head of Philanthropy | I29: NY | J29: 0 | O29: Ex-Arabella; Columbia Law | Q29: Foundation Management | R29: MFO | S29: 2. VM
B30: C K BLANDIN FOUNDATION | C30: =_xlfn.XLOOKUP(Table1[[#This Row],[EIN]],Sheet5!#REF!,Sheet5!#REF!) -> #REF! | D30: 46031 | E30: 218-326-0523 | F30: Kyle Erickson | G30: Director of Rural Grantmaking | H30: info@blandinfoundation.org | I30: MN | J30: #N/A | K30: 67 | L30: 416038619 | M30: 1.Excellent | O30: CEO: Tuleah Palmer. Also: Linda Gibeau (Grants Program Officer - Small Communities), Mary Magnuson (Grants Program Officer - Rural Placemaking). Toll-free: 877-882-2257. 100 North Pokegama Avenue, Grand Rapids, MN 55744. | S30: 2. VM
B31: CH ROBINSON WORLDWIDE FOUNDATION | C31: =_xlfn.XLOOKUP(Table1[[#This Row],[EIN]],Sheet5!#REF!,Sheet5!#REF!) -> #REF! | D31: 46031 | E31: 952-937-8500 | F31: Rachel Schwalbach | G31: VP, ESG & President of C.H. Robinson Foundation | H31: communityrelations@chrobinson.com | I31: SD | J31: #N/A | K31: 133 | L31: 680599299 | M31: 1.Excellent | O31: Rachel leads Foundation budget and strategy. Focus: Minneapolis-St. Paul metro. Since 2005, donated $29M to nonprofits. | S31: 2. VM | T31: 1/9 - Voicemail for evelyn
B32: CLAUDE WORTHINGTON BENEDUM FOUNDATION | C32: =_xlfn.XLOOKUP(Table1[[#This Row],[EIN]],Sheet5!#REF!,Sheet5!#REF!) -> #REF! | D32: 46031 | E32: 412-246-3634 | F32: Kim Tieman | G32: Vice President and Program Director | H32: info@benedum.org | I32: PA | J32: #N/A | K32: 42 | L32: 251086799 | M32: 1.Excellent | O32: President: Jen Giovannitti 412-246-3642. Sr Program Officers: Melanie Claxton 412-246-3624, Bill Woodrum 412-246-3644 (community/econ dev lead). Dir Strategic Initiatives: Rochelle Goodwin. 223 Fourth Ave, 1400 Benedum-Trees Bldg, Pittsburgh, PA 15222. | S32: 2. VM | T32: left a message for Jen (Kim's mailbox was full)
B33: Conrad & Virginia Klee Foundation | D33: 46031 | E33: 607-722-2266 | F33: Amanda McIntyre | G33: Executive Director | H33: amanda@kleefoundation.org | I33: NY | J33: Eastern | K33: 28 | L33: 156019821 | M33: 1.Excellent | N33: kleefoundation.org | O33: 14 CB grants. Office hours 9am-1pm M-F. Admin: Michele Duquella. 84 Court St, Suite 510, Binghamton, NY 13901. | R33: Foundation | S33: 2. VM
B34: Conrad N. Hilton Foundation | C34: =_xlfn.XLOOKUP(Table1[[#This Row],[EIN]],Sheet5!#REF!,Sheet5!#REF!) -> #REF! | D34: 46027 | E34: (818) 851-3700 | F34: Christie Cardenas ext 410 | G34: Program Officer, Opportunity Youth | I34: CA | J34: Pacific | K34: 170 | L34: 943100217 | M34: 1. Excellent | N34: https://www.hiltonfoundation.org/about/people/ | O34: Colorado Springs-based; statewide focus | Q34: Foundation | S34: 2. VM | T34: 1/5 - VM
B35: Cook Family Foundation | D35: 46031 | E35: 989-725-1621 | F35: Tom Cook | G35: Executive Director | I35: MI | J35: Eastern | K35: 7 | L35: 382283809 | M35: 1.Excellent | N35: cookfamilyfoundation.org | O35: Small foundation (7 grantees). 15 CB grants. Backup: Kelleigh Tanton kelleigh@cookfamilyfoundation.org. 120 W. Exchange St, Suite 202, Owosso, MI 48867. | R35: Foundation | S35: 2. VM
B36: CTrees | D36: 46027 | E36: (818) 354-1666 | F36: Sasan Saatchi | G36: CEO | I36: CA | J36: 0 | O36: Track carbon in every tree on the planet for natural climate solutions. | Q36: Nonprofit | R36: Environment | S36: 2. VM
B37: Elevate Charter Schools | D37: 46027 | E37: (203) 843-4890 | F37: Jeffrey Cirillo | G37: President | I37: CT | J37: 0 | O37: Developing high-performing charter schools with rigorous personalized education. | Q37: Nonprofit | R37: Education | S37: 2. VM
B38: EWING MARION KAUFFMAN FOUNDATION | C38: =_xlfn.XLOOKUP(Table1[[#This Row],[EIN]],Sheet5!#REF!,Sheet5!#REF!) -> #REF! | D38: 46031 | E38: (816) 932-1000 | F38: Allison Greenwood Bajracharya | G38: Chief Impact and Strategy Officer | I38: MO | J38: #N/A | K38: 103 | L38: 436064859 | M38: 1.Excellent | O38: New role 2024. KC native, formerly America Achieves. CEO: DeAngela Burns-Wallace. VP Programs: not listed. LinkedIn outreach recommended. 263 employees. | S38: 2. VM
B39: FAUQUIER HEALTH FOUNDATION | C39: =_xlfn.XLOOKUP(Table1[[#This Row],[EIN]],Sheet5!#REF!,Sheet5!#REF!) -> #REF! | D39: 46031 | E39: 540-680-4100 | F39: Beth Foddrell | G39: Program Officer | H39: bfoddrell@pathforyou.org | I39: VA | J39: #N/A | K39: 63 | L39: 300219424 | M39: 1.Excellent | O39: NOW CALLED PATH FOUNDATION (pathforyou.org). TA Grant explicitly funds "software for donor management". Also: Andy Johnston (Dir Programs). Fauquier/Rappahannock/Culpeper VA. | S39: 2. VM | T39: 1/7 - VM for margi 1/9- another VM for margi (not sure how to spell her name - she's a grants manager)
B40: First Interstate BancSystem Foundation | C40: =_xlfn.XLOOKUP(Table1[[#This Row],[EIN]],Sheet5!#REF!,Sheet5!#REF!) -> #REF! | D40: 46031 | E40: 406-255-5393 | F40: James Reuter | G40: Chair, Foundation Board of Directors | H40: firstinterstatefoundation@fib.com | I40: MT | J40: Mountain | K40: 538 | L40: 810465899 | M40: 1.Excellent | O40: Chair leads 5-member board. PO Box 7113, Billings MT 59103. LOI via nearest bank branch first. Focus: community development, leadership. | S40: 2. VM
B41: GERALDINE R DODGE FOUNDATION INC | C41: =_xlfn.XLOOKUP(Table1[[#This Row],[EIN]],Sheet5!#REF!,Sheet5!#REF!) -> #REF! | D41: 46029 | E41: 973-540-8442 | F41: Samra Haider | G41: President & CEO | H41: shaider@grdodge.org | I41: NJ | J41: #N/A | K41: 37 | L41: 237406010 | M41: 1.Excellent | O41: 61% capacity; 335 NJ grantees; racial wealth gap focus; new CEO June 2025; RECOMMENDED | S41: 2. VM
...

Sheet Sheet1
B2: 1. Not Contacted
B3: 2. VM
B4: 3. Talked to Someone
B5: 4. Reached Decision Maker
B6: 5. Interested

Sheet Sheet2
B2: Org | C2: Researched | D2: Date_Contacted | E2: Rating | F2: Why_Rating | G2: Pitch_Angle | H2: State | I2: EIN | J2: Assets | K2: Grantees | L2: Capacity_Pct | M2: Accepts_Apps | N2: Recommended_Contact | O2: Contact_Title | P2: Contact_Email | Q2: Phone | R2: Website | S2: About
B3: Ann Jackson Family Foundation | C3: 1 | E3: Excellent | F3: 98% capacity grants, small family foundation, 90% grants local to Santa Barbara | G3: Your 98% GOS rate shows commitment to nonprofit flexibility. TheGrantScout helps your Santa Barbara grantees find additional local funders. | H3: CA | I3: 953367511 | J3: 88737372 | K3: 152 | L3: 0.98 | M3: Yes | N3: Palmer Jackson Jr. | O3: Managing Trustee | P3: palmer.jackson@gmail.com | Q3: (805) 969-2258 | R3: ajff.org | S3: 98% capacity grants, small family foundation, 90% grants local to Santa Barbara
B4: California Wellness Foundation | C4: 1 | E4: Excellent | F4: 52% capacity grants, 1,326 grantees, known leader in core operating support, community nonprofits | G4: Your 52% GOS rate shows commitment to nonprofit sustainability. TheGrantScout helps your grantees discover other foundations aligned with their missions. | H4: CA | I4: 954292101 | J4: 1042135742 | K4: 1326 | L4: 0.52 | M4: Yes | N4: Monica Gomez | O4: Program Officer - Equity in Access | R4: calwellness.org | S4: 52% capacity grants, 1,326 grantees, known leader in core operating support, community nonprofits
B5: Conrad N. Hilton Foundation | C5: 1 | E5: Excellent | F5: 43% capacity grants, 1,637 grantees, funds intermediaries for capacity building, explicit capacity building focus | G5: You fund intermediaries for capacity building. TheGrantScout helps your 1,637 grantees find additional funders to diversify their revenue streams. | H5: CA | I5: 943100217 | J5: 7099706570 | K5: 1637 | L5: 0.43 | M5: Yes | N5: Christie Cardenas | O5: Program Officer - Opportunity Youth | R5: hiltonfoundation.org | S5: 43% capacity grants, 1,637 grantees, funds intermediaries for capacity building, explicit capacity building focus
B6: El Pomar Foundation | C6: 1 | E6: Good | F6: 31% capacity grants, 1,021 grantees, strong leadership programs, Colorado focus | G6: Your leadership programs build nonprofit capacity. TheGrantScout extends that support by helping grantees find additional Colorado funders. | H6: CO | I6: 846002373 | J6: 446140929 | K6: 1021 | L6: 0.31 | M6: Yes | N6: Matt Carpenter | O6: EVP & COO | P6: grants@elpomar.org | Q6: 719-633-7733 | R6: elpomar.org | S6: 31% capacity grants, 1,021 grantees, strong leadership programs, Colorado focus
B7: Fred Maytag Family Foundation | C7: 1 | E7: Good | F7: 76% capacity grants but only 81 grantees. Small grantee pool limits B2B scale. | G7: Your 76% GOS rate is strong but grantee pool (81) limits B2B scale. Could pilot with your Iowa/California grantees. | H7: CA | I7: 421444870 | J7: 67782266 | K7: 81 | L7: 0.76 | M7: Yes | N7: Frederick L. Maytag III | O7: CEO/Vice President | R7: N/A - mail only | S7: 76% capacity grants but only 81 grantees. Small grantee pool limits B2B scale. HQ: 3701 Sacramento St Suite 369, SF CA 94118
B8: Joseph Drown Foundation | C8: 1 | E8: Good | F8: 51% capacity grants, 193 grantees, LA County education focus, 70-yr history, professional staff | G8: Your 51% GOS focus on LA County education is solid. TheGrantScout helps your grantees discover additional Southern California education funders. | H8: CA | I8: 956093178 | J8: 104011094 | K8: 193 | L8: 0.51 | M8: Yes | N8: Alyssa Santino | O8: President of Programs & Operations | P8: alyssa@jdrown.org | Q8: (310) 277-4488 | R8: jdrown.org | S8: 51% capacity grants, 193 grantees, LA County education focus, 70-yr history, professional staff
B9: Lisa & Douglas Goldman Fund | C9: 1 | E9: Excellent | F9: 53% capacity grants, 328 grantees, Levi Strauss family, democracy/climate/education focus | G9: Your 53% capacity focus and democratic values align well. TheGrantScout helps your grantees build sustainable funding portfolios. | H9: CA | I9: 943167546 | J9: 270254108 | K9: 328 | L9: 0.53 | M9: Yes | N9: Nancy Kami | O9: Executive Director | P9: NKami@ldgfund.org (inferred) | Q9: 415-771-1717 | R9: ldgfund.org | S9: 53% capacity grants, 328 grantees, Levi Strauss family, democracy/climate/education focus
B10: Marie Lamfrom Charitable Foundation | C10: 1 | E10: Excellent | F10: 57% capacity grants, 958 grantees, expanded GOS & multi-year, BIPOC/LGBTQ+ focus, Oregon's #2 capacity builder | G10: You've expanded GOS & multi-year funding for sustainability. TheGrantScout helps your 958 Oregon grantees find additional funders to reduce single-funder dependence. | H10: OR | I10: 931254171 | J10: 388446637 | K10: 958 | L10: 0.57 | M10: Yes | N10: Tyler Hobbs | O10: President | P10: tyler@marielamfrom.org | R10: marielamfrom.org | S10: 57% capacity grants, 958 grantees, expanded GOS & multi-year, BIPOC/LGBTQ+ focus, Oregon's #2 capacity builder
B11: Meyer Memorial Trust | C11: 1 | E11: Excellent | F11: 37% capacity grants, 880 grantees, already partners with Resilia, Oregon's top capacity builder | G11: You already partner with Resilia for capacity building. TheGrantScout complements that - helping your 880 Oregon grantees find additional foundation funding. | H11: OR | I11: 930806316 | J11: 885167113 | K11: 880 | L11: 0.37 | M11: Yes | N11: Nancy Haque | O11: Director of Policy and Programs | P11: questions@mmt.org | Q11: 503-228-5512 | R11: mmt.org | S11: 37% capacity grants, 880 grantees, already partners with Resilia, Oregon's top capacity builder
B12: O.L. Halsell Foundation | C12: 1 | E12: Good | F12: 68% capacity grants, 118 grantees, Orange County youth focus, small OC nonprofits | G12: Your 68% capacity focus on Orange County youth orgs is strong. TheGrantScout helps these grantees discover additional Southern California funders. | H12: CA | I12: 956027266 | J12: 46370868 | K12: 118 | L12: 0.68 | M12: Yes | N12: W. David Stauffer Jr. | O12: President | Q12: (714) 546-0755 | S12: 68% capacity grants, 118 grantees, Orange County youth focus. No website. Mail: PO Box 6300, Santa Ana CA 92706
B13: Price Philanthropies Foundation | C13: 1 | E13: Excellent | F13: 93% capacity grants, 387 grantees, small City Heights nonprofits who need funding diversification | G13: Your 93% capacity focus on City Heights nonprofits is remarkable. TheGrantScout helps these small orgs find additional funders to reduce dependence on any single source. | H13: CA | I13: 465129465 | J13: 470624292 | K13: 387 | L13: 0.93 | M13: Invitation Only | N13: Sakara Tear | O13: Senior Director of Community Initiatives | P13: stear@pricephilanthropies.org | Q13: (619) 795-2000 | R13: pricephilanthropies.org | S13: 93% capacity grants, 387 grantees, small City Heights nonprofits who need funding diversification
B14: Ronald W. Naito MD Foundation | C14: 1 | E14: Good | F14: 64% capacity grants, 211 grantees, Oregon focus, pausing new apps = grantees need other funding | G14: You're pausing new applications - your existing grantees need other funding sources! TheGrantScout helps them find additional Oregon funders. | H14: OR | I14: 836622391 | J14: 38830815 | K14: 211 | L14: 0.64 | M14: Yes | N14: Kris Anderson | O14: Executive Director | P14: info@rwnfoundation.org | R14: rwnfoundation.org | S14: 64% capacity grants, 211 grantees, Oregon focus, pausing new apps = grantees need other funding
B15: The Crail-Johnson Foundation | C15: 1 | E15: Excellent | F15: 58% capacity grants, 199 grantees, San Pedro/South LA children focus, provides TA to grantees | G15: You already provide TA to grantees! TheGrantScout complements that - helping your San Pedro/South LA grantees find additional foundation funding. | H15: CA | I15: 330247161 | J15: 19589623 | K15: 199 | L15: 0.58 | M15: Yes | N15: Rachel Roth | O15: Executive Director | P15: rroth@crail-johnson.org | Q15: (310) 519-7413 | R15: crail-johnson.org | S15: 58% capacity grants, 199 grantees, San Pedro/South LA children focus, provides TA to grantees
B16: The Kresge Foundation | C16: 1 | E16: Good | F16: 29% capacity grants, 1,264 grantees, LIFT team with $2M/yr capacity building budget | G16: Your LIFT team has a $2M/yr capacity building budget. TheGrantScout could be part of your grantee support toolkit. | H16: MI | I16: 381359217 | J16: 4073115789 | K16: 1264 | L16: 0.29 | M16: Yes | N16: Neesha Modi | O16: Director, Program & Social Investment Operations | Q16: 248-643-9630 | R16: kresge.org | S16: 29% capacity grants, 1,264 grantees, LIFT team with $2M/yr capacity building budget
B17: The Satterberg Foundation | C17: 1 | E17: Excellent | F17: 82% capacity grants, 292 grantees, 300+ BIPOC-led partners, shifting to retention mode = grantees need other funding | G17: You're shifting to RETENTION mode - perfect timing! TheGrantScout helps your 300+ BIPOC-led partners find additional funders as you step back. | H17: WA | I17: 911501066 | J17: 443335399 | K17: 292 | L17: 0.82 | M17: Invitation Only | N17: Sarah Walczyk | O17: Executive Director | P17: swalczyk@satterberg.org | Q17: (206) 441-3045 | R17: sfrfoundation.org | S17: 82% capacity grants, 292 grantees, 300+ BIPOC-led partners, shifting to retention mode = grantees need other funding
B18: The William & Flora Hewlett Foundation | C18: 1 | E18: Good | F18: 32% capacity grants, 1,796 grantees, Effective Philanthropy Group, strong OE grants program | G18: Your Effective Philanthropy Group funds organizational effectiveness. TheGrantScout helps grantees become more sustainable through funding diversification. | H18: CA | I18: 941655673 | J18: 13332174215 | K18: 1796 | L18: 0.32 | M18: Yes | N18: Jehan Velji | O18: Director - Effective Philanthropy Group | P18: jvelji@hewlett.org | Q18: (650) 234-4500 | R18: hewlett.org | S18: 32% capacity grants, 1,796 grantees, Effective Philanthropy Group, strong OE grants program
B19: Weingart Foundation | C19: 1 | E19: Excellent | F19: 64% capacity grants, 872 grantees, unrestricted core support leader, LA-area community nonprofits | G19: Your 64% unrestricted funding shows deep commitment to nonprofit sustainability. TheGrantScout helps your 872 LA-area grantees find additional funders. | H19: CA | I19: 956054814 | J19: 866296097 | K19: 872 | L19: 0.64 | M19: Yes | N19: Joanna Jackson | O19: President & CEO | P19: jjackson@weingartfnd.org | Q19: (213) 688-7799 | R19: weingartfnd.org | S19: 64% capacity grants, 872 grantees, unrestricted core support leader, LA-area community nonprofits

Sheet Sheet3
B2: foundation name | C2: recommended contact | D2: why recommended | E2: contact name | F2: contact title | G2: contact email | H2: contact phone | I2: contact linkedin | J2: ein
B3: Conrad N. Hilton Foundation | C3: YES | D3: Primary contact with direct email/LinkedIn; most relevant for B2B pitch | E3: Christie Cardenas | F3: Program Officer - Opportunity Youth | I3: https://www.linkedin.com/in/christie-cardenas/ | J3: 943100217 | K3: 15+ years equity-focused grantmaking; manages capacity building grants
B4: Conrad N. Hilton Foundation | E4: Elizabeth Cheung | F4: Sr. Program Officer - Opportunity Youth | I4: https://www.linkedin.com/in/elizabeth-cheung-58a8544/ | J4: 943100217 | K4: Leads New Orleans portfolio including capacity building
B5: Conrad N. Hilton Foundation | E5: Angelina McCormick Soll LCSW | F5: Program Officer - Foster Youth | I5: https://www.linkedin.com/in/angelinasoll/ | J5: 943100217 | K5: Manages grants to Greater Horizons (capacity building intermediary)
B6: Conrad N. Hilton Foundation | E6: Caitlyn Pecoraro | F6: Sr. Advocacy Officer - Older Youth | I6: https://www.linkedin.com/in/caitlyn-pecoraro-9819a876/ | J6: 943100217 | K6: Bridges Foster Youth + Opportunity Youth programs
B7: California Wellness Foundation | C7: YES | D7: Primary contact with direct email/LinkedIn; most relevant for B2B pitch | E7: Monica Gomez | F7: Program Officer - Equity in Access | I7: https://www.linkedin.com/in/gomezmonica22/ | J7: 954292101 | K7: 20+ years capacity-building experience
B8: California Wellness Foundation | E8: Jennifer Wright | F8: Senior Program Officer | I8: https://www.linkedin.com/in/jennifer-wright-calwellness/ | J8: 954292101 | K8: Leads grantmaking initiatives; supports nonprofit organizations
B9: El Pomar Foundation | C9: YES | D9: Primary contact with direct email/LinkedIn; most relevant for B2B pitch | E9: Matt Carpenter | F9: EVP & COO | H9: 719-633-7733 | J9: 846002373 | K9: Oversees grants & programs; Fellowship alum
B10: El Pomar Foundation | E10: Grants Office | G10: grants@elpomar.org | H10: 719-633-7733 | J10: 846002373 | K10: General grants inquiries
B11: El Pomar Foundation | E11: Erin Hannan | F11: SVP Communications | H11: 719-577-5750 | J11: 846002373 | K11: Communications lead
B12: Meyer Memorial Trust | C12: YES | D12: Primary contact with direct email/LinkedIn; most relevant for B2B pitch | E12: Nancy Haque | F12: Director of Policy and Programs | I12: https://www.linkedin.com/in/nancy-haque-8470305/ | J12: 930806316 | K12: Decision-maker for programs
B13: Meyer Memorial Trust | E13: Huy Ong | F13: Senior Program Officer - Our Resilient Places | I13: https://www.linkedin.com/in/huy-ong-a73bb23/ | J13: 930806316 | K13: Climate and resilience portfolio
B14: Meyer Memorial Trust | E14: Allister Byrd | F14: Senior Program Officer - Justice Oregon | I14: https://www.linkedin.com/in/allister-byrd-03b27382/ | J14: 930806316 | K14: $25M Black-led orgs initiative
B15: Meyer Memorial Trust | E15: Sally Yee | F15: Program Officer | I15: https://www.linkedin.com/in/sally-yee-11398853/ | J15: 930806316
B16: Meyer Memorial Trust | E16: General Contact | G16: questions@mmt.org | H16: 503-228-5512 | J16: 930806316 | K16: General inquiries
B17: The California Endowment | C17: YES | D17: Primary contact with direct email/LinkedIn; most relevant for B2B pitch | J17: 954523232 | K17: Large funder but preselected only - not accepting applications
B18: Gordon E. and Betty I. Moore Foundation | C18: YES | D18: Primary contact with direct email/LinkedIn; most relevant for B2B pitch | E18: Aileen Lee | F18: President (Chief of Programs) | H18: 650-213-3000 | I18: https://www.linkedin.com/in/aileen-lee-a404baa2/ | J18: 943397785 | K18: Oversees all programs; no capacity building focus
B19: Gordon E. and Betty I. Moore Foundation | E19: Ignacio Estrada | F19: Director, Grants Administration | G19: i***@moore.org | H19: 650-213-3000 | J19: 943397785 | K19: 12+ years grants admin experience
B20: Gordon E. and Betty I. Moore Foundation | E20: Jennifer Rea Sandin | F20: Director, Program Operations | H20: 650-213-3000 | I20: https://www.moore.org/people-detail?personUrl=jenniferr | J20: 943397785 | K20: Program operations lead
B21: Gordon E. and Betty I. Moore Foundation | E21: General Contact | G21: communications@moore.org | H21: 650-213-3000 | J21: 943397785 | K21: HQ: 1661 Page Mill Road, Palo Alto CA
B22: The William & Flora Hewlett Foundation | C22: YES | D22: Primary contact with direct email/LinkedIn; most relevant for B2B pitch | E22: Jehan Velji | F22: Director - Effective Philanthropy Group | G22: jvelji@hewlett.org | H22: (650) 234-4500 | I22: https://www.linkedin.com/in/jehan-velji/ | J22: 941655673 | K22: 30+ yrs capacity building; leads OE program; former Blue Meridian; Harvard MBA
B23: The William & Flora Hewlett Foundation | E23: Jennifer Wei | F23: Organizational Effectiveness Officer | G23: jwei@hewlett.org | I23: https://www.linkedin.com/in/jennifer-wei-23477/ | J23: 941655673 | K23: Oversees capacity grants across all programs; Stanford MBA
B24: The William & Flora Hewlett Foundation | E24: Amber D. Miller | F24: President | G24: amiller@hewlett.org | H24: (650) 234-4500 | J24: 941655673 | K24: New president Sept 2024; sets foundation direction
B25: Weingart Foundation | C25: YES | D25: Primary contact with direct email/LinkedIn; most relevant for B2B pitch | E25: Joanna Jackson | F25: President & CEO | G25: jjackson@weingartfnd.org | H25: (213) 688-7799 | I25: https://www.linkedin.com/in/joanna-jackson-91484027 | J25: 956054814 | K25: New CEO June 2024; 15 yrs at Weingart; board of GEO & SoCal Grantmakers
B26: Weingart Foundation | E26: Crystal Crawford | F26: Sr. Director of Strategic Partnerships | G26: ccrawford@weingartfnd.org | H26: (213) 688-7799 | J26: 956054814 | K26: NEW ROLE 2024 - manages key stakeholder relationships; former ED Western Center on Law & Poverty
B27: Weingart Foundation | E27: Joyce Ybarra | F27: Vice President of Programs | G27: jybarra@weingartfnd.org | H27: (213) 688-7799 | J27: 956054814 | K27: Oversees grantmaking & learning programs; 15+ yrs at foundation; MPH UCLA
B28: Weingart Foundation | E28: Eric Medina | F28: Senior Program Officer | H28: (213) 688-7799 | J28: 956054814 | K28: 12+ yrs at Weingart; promoted May 2024
B29: Weingart Foundation | E29: Rosa Benitez | F29: Director of Program Investments | H29: (213) 688-7799 | J29: 956054814 | K29: Oversees grant investments
B30: Temple Hoyne Buell Foundation | C30: YES | D30: Primary contact with direct email/LinkedIn; most relevant for B2B pitch | E30: Laura Carlson | F30: Vice President of Programs | H30: 303-744-1688 | I30: https://www.linkedin.com/in/laura-carlson-4425513/ | J30: 846037604 | K30: 15 yrs at Buell; chairs CO Early Childhood Funders Network; decision-maker for grants
B31: Temple Hoyne Buell Foundation | E31: Steve ErkenBrack | F31: President & CEO | G31: s***@buellfoundation.org | H31: 303-744-1688 | J31: 846037604 | K31: Started Jan 2023; former DA & Chief Deputy AG Colorado; 10 yrs on board before CEO
B32: Temple Hoyne Buell Foundation | E32: Jason Callegari | F32: Director of Initiatives | H32: 303-744-1688 | J32: 846037604 | K32: Leads local financing initiatives; background in early childhood policy
B33: Temple Hoyne Buell Foundation | E33: Lesa Nesbit | F33: Senior Program Officer Supervisor | H33: 303-744-1688 | J33: 846037604 | K33: Manages grant review process; relationships with nonprofits
B34: Temple Hoyne Buell Foundation | E34: General Contact | G34: info@buellfoundation.org | H34: 303-744-1688 | J34: 846037604 | K34: HQ: 1873 S Bellaire St Suite 600 Denver CO 80222
B35: The Kresge Foundation | C35: YES | D35: Primary contact with direct email/LinkedIn; most relevant for B2B pitch | E35: Neesha Modi | F35: Director, Program & Social Investment Operations | H35: 248-643-9630 | I35: https://www.linkedin.com/in/neeshamodi/ | J35: 381359217 | K35: LEADS LIFT team; $2M/yr capacity building budget; ex-Deloitte talent strategy
B36: The Kresge Foundation | E36: Caroline Altman Smith | F36: Deputy Director, Education | H36: 248-643-9630 | I36: https://www.linkedin.com/in/cbasmith | J36: 381359217 | K36: LIFT founder; created FUEL program; on Council of Michigan Foundations board
B37: The Kresge Foundation | E37: Shamar A. Bibbins | F37: Managing Director, Environment | H37: 248-643-9630 | I37: https://www.linkedin.com/in/shamarbibbins/ | J37: 381359217 | K37: $23M Climate Change Health Equity initiative; promoted 2024
B38: Arnold and Mabel Beckman Foundation | C38: YES | D38: Primary contact with direct email/LinkedIn; most relevant for B2B pitch | E38: Dr. Anne Hultgren | F38: Executive Director & CEO | H38: 949-721-2222 | J38: 953169713 | K38: *100% is misleading - all grants use generic purpose text; grantees are research universities not nonprofits
B39: Arnold and Mabel Beckman Foundation | E39: Catrina Bryant | F39: Deputy Director | H39: 949-721-2222 | J39: 953169713 | K39: Oversees programs team; CPA; MBA Pepperdine
B40: Arnold and Mabel Beckman Foundation | E40: Nicole Patras | F40: Sr. Program Officer | H40: 949-721-2222 | I40: https://www.linkedin.com/in/nicole-patras-9a823a8b/ | J40: 953169713 | K40: Leads Beckman Young Investigator Program; heads JEDI committee
B41: Arnold and Mabel Beckman Foundation | E41: General Contact | G41: info@beckman-foundation.org | H41: 949-721-2222 | J41: 953169713 | K41: HQ: Irvine CA; focus on scientific research at elite universities
...

Sheet Sheet4
C2: 1875 Finance | E2: +41-22-310-1875 | F2: TBD | G2: Philanthropy Advisory | I2: CH | M2: Swiss | N2: Foundation Management | O2: MFO
C3: Alliance for Innovative Regulation | E3: (917) 446-5425 | F3: David Ehrich | G3: Executive Director | I3: DC | M3: Promoting responsible innovation to solve financial services challenges. | N3: Nonprofit | O3: Education
C4: Arnold and Mabel Beckman Foundation | F4: Bad | I4: CA | K4: 953169713 | M4: Science focus; very high capacity %
C5: Atkinson Foundation | E5: 650-876-0222 | I5: CA | K5: 946075613 | M5: Bay Area
C6: Austin Justice Coalition | E6: (512) 576-8152 | F6: Chas Moore | G6: Executive Director | I6: TX | M6: Improving quality of life for people of color in Austin. | N6: Nonprofit | O6: Human Services
C7: Ballentine Partners | E7: 781-314-1300 | F7: TBD | G7: Philanthropy Advisory | I7: MA | M7: Fee-only | N7: Foundation Management | O7: MFO
C8: Bangor Savings Bank Foundation | E8: (877) 226-4671 | F8: Foundation Team | G8: Foundation Staff | I8: ME | L8: https://www.bangor.com/the-bangor-savings-bank-foundation | M8: Battle Creek, MI; use Concierge Desk for inquiries | N8: Foundation
C9: Bess J. Hodges Foundation | I9: CA | K9: 330046140 | M9: Very high capacity %
C10: Blue Shield of California Foundation | E10: 415-901-3200 | I10: CA | K10: 942822302 | M10: Healthcare focus; good network
C11: Brittingham Family Foundation | I11: CA | K11: 262992045 | M11: San Diego
C12: Caprock | E12: 208-368-9600 | F12: Sophie Kelly | G12: Director of Impact Investments | I12: PA | M12: Impact investing | N12: Foundation Management | O12: MFO
C13: Charlotte Y. Martin Foundation | I13: WA | K13: 472057123 | M13: Washington; high capacity %
C14: Coda Media | E14: (650) 208-6846 | F14: Natalia Antelava | G14: CEO & Editor-in-Chief | I14: NY | M14: Publishing news articles on global crises - making complex issues accessible. | N14: Nonprofit | O14: Media
C15: Competency-Based Education Network | E15: (615) 517-1256 | F15: Charla Sheid Long | G15: President | I15: TN | M15: Catalyzing competency and skills-first society for all individuals. | N15: Nonprofit | O15: Education
C16: Conrad Prebys Foundation | E16: 858-565-6480 | I16: CA | K16: 203216993 | M16: $1.1B assets; San Diego
C17: Crescent Grove | E17: 847-752-9479 | F17: TBD | G17: Philanthropy Advisory | I17: WI | M17: Midwest | N17: Foundation Management | O17: MFO
C18: Crestview Academy | E18: (715) 835-2275 | F18: Margaret Waldhart-Larsen | G18: President | I18: WI | M18: Helping students reach potential academically and morally. | N18: Nonprofit | O18: Education
C19: CS Fund | I19: CA | K19: 953607882
C20: Descendants Truth and Reconciliation | E20: (225) 297-1120 | F20: La June Montgomery Tabron | G20: President & CEO | I20: LA | M20: Supporting truth-seeking, racial healing and transformation programs. | N20: Nonprofit | O20: Civil Rights
C21: Dogwood Health Trust | E21: (828) 771-6710 | F21: Grants Help Desk | G21: Via Grants Help Desk | I21: NC | L21: https://dogwoodhealthtrust.org/about/meet-the-team/ | M21: Los Angeles-based; Southern California focus | N21: Foundation
C22: Educopia Institute | E22: (404) 532-9766 | F22: Jessica Meyerson | G22: Co-Executive Director | I22: GA | M22: Connecting diverse knowledge communities with resources and power. | N22: Nonprofit | O22: Arts & Culture
C23: Elmina B. Sewall Foundation | E23: (207) 373-9206 | F23: Laura Dover | G23: Grants Contact | I23: ME | L23: https://sewallfoundation.org/staff-board | M23: ~130 employees; ~$631M annual grantmaking; ~3,000 active grants | N23: Foundation
C24: Firedoll Foundation | I24: CA | K24: 943301999
C25: Fleishhacker Foundation | E25: 415-561-5350 | I25: CA | K25: 946051048 | M25: SF Bay Area
C26: Foundation Source | E26: 800-839-0054 | F26: Elizabeth Wong | G26: Head of Philanthropic Advisory | I26: CT | M26: TOP TARGET | N26: Foundation Management | O26: MFO
C27: Fred Maytag Family Foundation | F27: Frederick L. Maytag III | G27: CEO/Vice President | I27: CA | J27: 2. Good | K27: 421444870
C28: Frontlines International | E28: (813) 293-6206 | F28: Charles White | G28: President | I28: FL | M28: Supporting persecuted Christians worldwide. | N28: Nonprofit | O28: Human Services
C29: FThree Foundation | I29: CA | K29: 943376857
C30: Fusion Global | E30: (856) 341-0396 | F30: Jason Sobel | G30: President | I30: NJ | M30: Connecting old and new to bring faith alive in new ways. | N30: Nonprofit | O30: Religion
C31: Gaia Fund | I31: CA | K31: 943215541 | M31: Environment focus
C32: Gaylord and Dorothy Donnelley Foundation | E32: (312) 977-2700 | F32: Foundation Staff | G32: Program Officer | I32: IL | L32: https://gddf.org/about/staff/ | M32: Board Chair: Linda Hilton; $7B+ in assets | N32: Foundation
C33: Global 70 MFO | D33: 46027 | E33: TBD | F33: TBD | G33: Philanthropy Advisory | I33: HK | M33: Network of 70 families | N33: Foundation Management | O33: MFO
C34: Global Food Partners | E34: (727) 237-6223 | F34: Elissa Lane | G34: President & CEO | I34: DC | M34: Improving conditions for animals in food supply chain - cage-free eggs focus. | N34: Nonprofit | O34: Food & Nutrition
C35: Gresham Partners | E35: 312-327-5020 | F35: TBD | G35: Philanthropy Advisory | I35: IL | M35: Pritzker connections | N35: Foundation Management | O35: MFO
C36: Growth Opportunity Partners | E36: (216) 462-0600 | F36: Michael Jeans | G36: President | I36: OH | M36: Advisory services for under-resourced communities to improve quality of life. | N36: Nonprofit | O36: Community Improvement
C37: Hatch Inc | E37: (317) 331-3364 | F37: Daniel Leckie | G37: Executive Director | I37: IN | M37: Hatch for Hunger connects egg producers with food banks - 11M eggs in 36 states. | N37: Nonprofit | O37: Food & Nutrition
C38: Hero's Journey Foundation | E38: (412) 363-1530 | F38: Michael Mervosh | G38: Executive Director | I38: PA | M38: Adventures and experiences for individuals seeking spirit and aliveness. | N38: Nonprofit | O38: Mental Health
C39: Hottinger Group | E39: +44-20-7399-0000 | F39: TBD | G39: Philanthropy Advisory | I39: UK | M39: Rothschild 2025 | N39: Foundation Management | O39: MFO
C40: Houston Endowment | E40: (713) 238-8100 | F40: Communications Team | G40: Via Invited Process | I40: TX | L40: https://houstonendowment.org/about/people | N40: Foundation
C41: Hutton Foundation | I41: CA | K41: 330779894
...

Sheet Sheet5
B3: Rating | C3: Foundation Name | D3: State | E3: Time Zone | F3: Assets | G3: Grantees | H3: Contact Name | I3: Contact Title | J3: Email | K3: Phone | L3: LinkedIn | M3: Website | N3: Why This Rating | O3: Notes | P3: EIN
A4: =_xlfn.XLOOKUP(P4,Calls!L:L,Calls!B:B) -> MEDINA FOUNDATION | B4: Excellent | C4: MEDINA FOUNDATION | D4: WA | E4: Pacific | F4: 103615717 | H4: Jennifer Teunon | I4: Executive Director | K4: 206-652-8783 | N4: Puget Sound human services focus. 4 CB service grants. Funds racial equity, general operating. SUNSETTING 3-5 years - grantees urgently need other funders. | O4: $104M assets. Top grantees: YMCA Seattle, Plymouth Housing, DESC, Housing Hope - all community nonprofits. Staff: Jessica Case & Aana Lauckhart (Senior Program Officers), Alexia Casiano (Grants Manager). No longer accepting new LOIs as of July 2025. Address: 801 2nd Ave #1108, Seattle WA 98104. | P4: 910745225
A5: =_xlfn.XLOOKUP(P5,Calls!L:L,Calls!B:B) -> HELLMAN FOUNDATION | B5: Excellent | C5: HELLMAN FOUNDATION | D5: CA | E5: Pacific | F5: 635837954 | H5: Dorian Luey | I5: Director, Capacity Building | K5: 415-837-5408 | N5: SF Bay Area community focus. Funds health equity, education, youth development, food access. Has capacity building director. Sunsetting by 2034 - grantees need help finding other funders. | O5: $636M assets. Managed by Third Plateau. ED: Annie Ulevitch. Collaborative Change Initiative. $310M granted to date. Accelerating giving before 2034 sunset. Media: media@thirdplateau.com. Address: 595 Market St #820, SF CA 94105. | P5: 611583546
A6: =_xlfn.XLOOKUP(P6,Calls!L:L,Calls!B:B) -> RAIKES FOUNDATION | B6: Excellent | C6: RAIKES FOUNDATION | D6: WA | E6: Pacific | F6: 90404225 | H6: Dr. Zoe Stemm-Calderon | I6: Executive Director (starting Jan 2026) | J6: info@raikesfoundation.org | K6: (206) 801-9500 | N6: Seattle-based, national reach. 7 CB service grants. Funds education, youth homelessness, democracy/equity. Top grantees include Seattle Foundation, National Equity Project. | O6: $90M assets. Founded by Jeff & Tricia Raikes (Microsoft). Chief of Staff: Fatima Gulamali. ~24 employees. Focus: K-12 education, youth housing stability, impact philanthropy, community organizing. Address: 2157 N Northlake Way #220, Seattle WA 98103. | P6: 912173492
A7: =_xlfn.XLOOKUP(P7,Calls!L:L,Calls!B:B) -> SEMPRA FOUNDATION | B7: Excellent | C7: SEMPRA FOUNDATION | D7: CA | E7: Pacific | F7: 14132710 | G7: 688 | H7: Christy Ihrig | I7: Director | K7: 619-696-2467 | M7: WWW.SEMPRAFOUNDATION.ORG | N7: 688 dependent grantees - massive reach. 2,382 grants last year. Corporate foundation of Sempra Energy in San Diego. Focus: education, environment, emergency preparedness. High-volume grantor with broad community impact. | O7: Address: 488 8th Avenue, HQ08S3, San Diego CA 92101. Also: Andy Carrasco (Director). Recent grantees: Monarch School (homeless youth), MAAC (anti-poverty), Voices for Children (CASAs). Online application portal available. Founded 2007, invested $50M+. | P7: 261325469
A8: =_xlfn.XLOOKUP(P8,Calls!L:L,Calls!B:B) -> First Interstate BancSystem Foundation | B8: Excellent | C8: First Interstate BancSystem Foundation | D8: MT | E8: Mountain | F8: 20270202 | G8: 538 | H8: Mr. Reuter | I8: Chair, Foundation Board of Directors | J8: firstinterstatefoundation@fib.com | K8: 406-255-5393 | M8: firstinterstatebank.com | O8: Chair leads 5-member board. PO Box 7113, Billings MT 59103. LOI via nearest bank branch first. Focus: community development, leadership. | P8: 810465899
A9: =_xlfn.XLOOKUP(P9,Calls!L:L,Calls!B:B) -> THE COLORADO HEALTH FOUNDATION | B9: Excellent | C9: THE COLORADO HEALTH FOUNDATION | D9: CO | E9: Mountain | F9: 2822619846 | G9: 238 | H9: Karen McNeil-Miller | I9: President and CEO | K9: 303-953-3628 | M9: WWW.COLORADOHEALTH.ORG | N9: $2.8 BILLION assets - largest foundation in batch by far. 238 dependent Colorado grantees. Professional staff with CEO, Chief Impact Officer, VP Philanthropy - all with direct phone numbers. Major health equity funder. | O9: Chief Impact Officer: Bruce Byington (303.953.3689). VP Philanthropy: Amy Latham (303.953.3670). Main: 303-953-3600. Address: 1780 Pennsylvania St, Denver CO 80203. Focus: health equity in Colorado. Top grantees: Trailhead Institute, Latino Community Foundation, Ute tribes, Denver Foundation. | P9: 742568941
A10: =_xlfn.XLOOKUP(P10,Calls!L:L,Calls!B:B) -> The Ford Family Foundation | B10: Excellent | C10: The Ford Family Foundation | D10: OR | E10: Pacific | F10: 1125032912 | G10: 171 | H10: Keavy Cook | I10: Vice President of Programs | J10: keavy@tfff.org | K10: (541) 957-5574 | L10: https://www.linkedin.com/in/keavy-cook-ab758110/ | M10: www.tfff.org | N10: 171 dependent rural Oregon grantees. 64 CB grants for strategic planning. VP of Programs (Keavy Cook) newly promoted Dec 2024 with direct email. | O10: Promoted Dec 2024. Also: Kasi Allen (VP Learning & Impact). HQ: Roseburg OR. | P10: 936026156
A11: =_xlfn.XLOOKUP(P11,Calls!L:L,Calls!B:B) -> Conrad N. Hilton Foundation | B11: Excellent | C11: CONRAD N HILTON FOUNDATION | D11: CA | E11: Pacific | F11: 7099706570 | G11: 170 | H11: Christie Cardenas | I11: Program Officer - Opportunity Youth | J11: ccardenas@hiltonfoundation.org | L11: https://www.linkedin.com/in/christie-cardenas/ | M11: WWW.HILTONFOUNDATION.ORG | O11: 15+ years equity-focused grantmaking. Email pattern based on CEO Peter Laugharn (plaugharn@hiltonfoundation.org). LinkedIn: linkedin.com/in/christie-cardenas/ | P11: 943100217
A12: =_xlfn.XLOOKUP(P12,Calls!L:L,Calls!B:B) -> MARIE LAMFROM CHARITABLE FOUNDATION | B12: Excellent | C12: MARIE LAMFROM CHARITABLE FOUNDATION | D12: OR | E12: Pacific | F12: 374872001 | G12: 149 | H12: Tyler Hobbs | I12: President | J12: tyler@marielamfrom.org | L12: https://www.linkedin.com/in/johntylerhobbs/ | M12: WWW.MARIELAMFROM.ORG | O12: 57% capacity; 958 grantees; expanded GOS & multi-year; BIPOC/LGBTQ+ focus; Oregon's #2 capacity builder | P12: 931254171
A13: =_xlfn.XLOOKUP(P13,Calls!L:L,Calls!B:B) -> M J MURDOCK CHARITABLE TRUST | B13: Excellent | C13: M J MURDOCK CHARITABLE TRUST | D13: WA | E13: Pacific | F13: 1892899273 | G13: 134 | H13: Kimberly Thornbury, Ph.D. | I13: Vice President, Programs & Partnerships | J13: info@murdocktrust.org | K13: (360) 694-8415 | L13: https://www.linkedin.com/in/kimberly-thornbury-12451b28/ | M13: WWW.MURDOCKTRUST.ORG | N13: 134 dependent grantees in Pacific NW, 59 CB grants. VP Programs focuses on board governance, exec leadership, fundraising capacity. | O13: Also: Jill Lemke (VP Grants Mgmt), Pauline Fong (Chief Program Officer). Focus: AK, ID, MT, OR, WA. Free nonprofit resources. | P13: 237456468
A14: =_xlfn.XLOOKUP(P14,Calls!L:L,Calls!B:B) -> The California Wellness Foundation | B14: Excellent | C14: THE CALIFORNIA WELLNESS FOUNDATION | D14: CA | E14: Pacific | F14: 1042135742 | G14: 126 | H14: Monica Gomez | I14: Program Officer - Equity in Access & Economic Security | J14: info@calwellness.org | K14: 818-702-1900 | L14: https://www.linkedin.com/in/gomezmonica22/ | M14: WWW.CALWELLNESS.ORG | O14: 20+ years nonprofit experience. Focuses on capacity-building for social change orgs. LA: 818-702-1900, Oakland: 415-908-3000. No direct emails published. | P14: 954292101
A15: =_xlfn.XLOOKUP(P15,Calls!L:L,Calls!B:B) -> The James Irvine Foundation | B15: Excellent | C15: The James Irvine Foundation | D15: CA | E15: Pacific | F15: 3300619484 | G15: 109 | H15: Don Howard | I15: President & CEO | J15: dhoward@irvine.org | L15: www.irvine.org | M15: www.Irvine.org | O15: Direct CEO email confirmed. Also: Cindy Downing (Program Officer, manages Leadership Awards). 1 Bush St Ste 800, San Francisco CA 94104. ~80 employees. $158.7M grants in 2024. | P15: 941236937
A16: =_xlfn.XLOOKUP(P16,Calls!L:L,Calls!B:B) -> Meyer Memorial Trust | B16: Excellent | C16: MEYER MEMORIAL TRUST | D16: OR | E16: Pacific | F16: 885167113 | G16: 107 | H16: Nancy Haque | I16: Director of Policy and Programs | J16: questions@mmt.org | K16: 503-228-5512 | L16: https://www.linkedin.com/in/nancy-haque-8470305/ | M16: WWW.MMT.ORG | O16: Decision-maker for programs | P16: 930806316
A17: =_xlfn.XLOOKUP(P17,Calls!L:L,Calls!B:B) -> THE ROUNDHOUSE FOUNDATION | B17: Excellent | C17: THE ROUNDHOUSE FOUNDATION | D17: OR | E17: Pacific | F17: 358883108 | G17: 91 | H17: Erin Borla | I17: Executive Director & Trustee | J17: erin@roundhousefoundation.org | K17: 541-904-0700 | M17: https://roundhousefoundation.org | N17: 91 dependent grantees (rural Oregon nonprofits). 6 CB service grants including strategic planning and technical assistance. Professional staff with direct emails on website. | O17: Key staff: Rebeckah Berry (Grants Program Director) rebeckah@roundhousefoundation.org, Chaney Coman (Grants Manager) chaney@roundhousefoundation.org. Focus: rural Oregon and tribal communities. Grants $500-$30K. Small Grants open Jan-Nov. Open Calls: Spring (Jan-Mar) and Fall (Jun-Aug). | P17: 226930631
A18: =_xlfn.XLOOKUP(P18,Calls!L:L,Calls!B:B) -> Weingart Foundation | B18: Excellent | C18: WEINGART FOUNDATION | D18: CA | E18: Pacific | F18: 866296097 | G18: 61 | H18: Joanna Jackson | I18: President & CEO | J18: jjackson@weingartfnd.org | K18: (213) 688-7799 | L18: https://www.linkedin.com/in/joanna-jackson-91484027 | M18: WWW.WEINGARTFND.ORG | O18: New CEO June 2024; 15 yrs at Weingart; board of GEO & SoCal Grantmakers | P18: 956054814
A19: =_xlfn.XLOOKUP(P19,Calls!L:L,Calls!B:B) -> THE COLLINS FOUNDATION | B19: Excellent | C19: THE COLLINS FOUNDATION | D19: OR | E19: Pacific | F19: 227675139 | G19: 50 | H19: Sara Yada | I19: Program Officer | J19: information@collinsfoundation.org | K19: 503-227-7171 | M19: https://www.collinsfoundation.org | N19: 50 Oregon community nonprofits. $10M/year grantmaking. $310M+ awarded since 1947. Professional staff with direct contact. | O19: Founded 1947. 1618 SW First Ave Suite 505, Portland OR. Focus: arts, education, health equity, environment. Note: Responsive grants paused until late Spring 2025 for program redesign. | P19: 936021893
A20: =_xlfn.XLOOKUP(P20,Calls!L:L,Calls!B:B) -> SIERRA HEALTH FOUNDATION | B20: Excellent | C20: SIERRA HEALTH FOUNDATION | D20: CA | E20: Pacific | F20: 57860059 | G20: 45 | H20: Chet P. Hewitt | I20: President and CEO | J20: info@sierrahealth.org | K20: 916-922-4755 | L20: https://www.linkedin.com/in/chet-hewitt-5a1988277/ | M20: WWW.SIERRAHEALTH.ORG | N20: 45 dependent grantees focused on health equity and vulnerable youth. Professional leadership team with 17+ year CEO tenure. Strong focus on community health disparities in Sacramento/Northern CA region. | O20: SVP Programs: Kaying Hang. COO/CFO: Edward Harris. Multiple program officers. 1321 Garden Hwy, Sacramento CA 95833. Founded 1984. Also operates The Center at Sierra Health Foundation (nonprofit intermediary). | P20: 680050036
A21: =_xlfn.XLOOKUP(P21,Calls!L:L,Calls!B:B) -> SAMUELI FOUNDATION | B21: Excellent | C21: SAMUELI FOUNDATION | D21: CA | E21: Pacific | F21: 45536119 | G21: 45 | H21: Annette Fritzsche | I21: Director of Grants Management | J21: info@samueli.org | K21: 949-760-4400 | M21: https://www.samueli.org | N21: 45 Orange County nonprofits. Major programs: Breakaway Fund ($11M), Build OC Fund (up to $1M capital grants). Very active. | O21: Founded 1998 by Henry & Susan Samueli (Giving Pledge). Corona Del Mar CA. Breakaway Fund: $50-100K grants. Build OC Fund: up to $1M capital. 2026 funding cycles confirmed. Also: Dr. Shauntina Sorrells (Chief Program Officer background). | P21: 330758237
A22: =_xlfn.XLOOKUP(P22,Calls!L:L,Calls!B:B) -> SUNLIGHT GIVING | B22: Excellent | C22: SUNLIGHT GIVING | D22: CA | E22: Pacific | F22: 471220977 | G22: 44 | H22: Cedrick Andrews | I22: Program Director | L22: https://www.linkedin.com/in/cedrickandrews/ | M22: HTTP://WWW.SUNLIGHTGIVING.ORG/ | N22: 44 dependent Silicon Valley grantees - all community nonprofits serving low-income families (LifeMoves, Second Harvest Food Banks, Abode Services). 9 CB service grants including organizational development and strategic planning. Professional program team with dedicated grants manager. | O22: Brian Acton (WhatsApp founder) family foundation. Part of Wildcard Giving. Program Officers: Sepi Aghdaee, Jessica Avendano, Erika Matadamas. Grants Manager: Kelsey Leuchars. Focus: young children and families in poverty in Silicon Valley. No direct contact info on website - use LinkedIn. Address: 855 El Camino Real Bldg 4 Ste 200, Palo Alto CA 94301. | P22: 471820379
A23: =_xlfn.XLOOKUP(P23,Calls!L:L,Calls!B:B) -> MARSHALL L AND PERRINE D MCCUNE | B23: Excellent | C23: MARSHALL L AND PERRINE D MCCUNE | D23: NM | E23: Mountain | F23: 91819670 | G23: 43 | H23: Carla Romero | I23: Executive Director | J23: mccune@nmmccune.org | K23: 505-983-8300 | L23: www.nmmccune.org | M23: WWW.NMMCCUNE.ORG | O23: Also: Ernesto Torres (Dir Grantmaking & Community Inclusion), Henry Rael (Dir Strategy), Allison Hagerman (Dir Learning & Ops). 345 E Alameda St, Santa Fe NM 87501. grants@nmmccune.org for grantmaking. | P23: 850429439
A24: =_xlfn.XLOOKUP(P24,Calls!L:L,Calls!B:B) -> The McConnell Foundation | B24: Excellent | C24: The McConnell Foundation | D24: CA | E24: Pacific | F24: 420547459 | G24: 39 | H24: John A. Mancasola | I24: President & CEO | K24: 530-226-6200 | M24: HTTP://WWW.MCCONNELLFOUNDATION.ORG | N24: $420M assets, 39 dependent grantees in Shasta County/Redding CA. Full professional staff with direct phone lines. Major regional funder supporting local community foundations, education, and environment. | O24: COO: Shannon Phillips (530-226-6231). Dir Children/Youth/Ed: Kelly Salter (530-226-6232). Dir College Success: David Tanner (530-226-6233). Dir Ecosystem Resilience: Alex Carter (530-226-6249). Executive Asst: Marie Welch (530-226-6217). Mancasola has been director since 1991. | P24: 946102700
